Workbook

Sheet RZiS ->>>

Sheet Check RZiS
A3: Etykiety wierszy | B3: Suma z 2025 | G3: Etykiety wierszy | H3: Suma z 2024
A4: A. Przychody netto ze sprzedaży i zrównane z nimi, w tym: | B4: 22183111 | G4: A. Przychody netto ze sprzedaży i zrównane z nimi, w tym: | H4: 21358215
A5: B. Koszty działalności operacyjnej | B5: 21801950 | G5: B. Koszty działalności operacyjnej | H5: 21107239
A6: D. Pozostałe przychody operacyjne | B6: 126275.61 | G6: D. Pozostałe przychody operacyjne | H6: 482321.98
A7: E. Pozostałe koszty operacyjne | B7: 18914.54 | G7: E. Pozostałe koszty operacyjne | H7: 19294.28
A8: G. Przychody finansowe | B8: 18.29 | G8: G. Przychody finansowe | H8: 362.63
A9: H. Koszty finansowe | B9: 5152.3 | G9: H. Koszty finansowe | H9: -5155.11
A10: J. Podatek dochodowy | B10: 158751.35 | G10: J. Podatek dochodowy | H10: 377232.61
A11: Suma końcowa | B11: 44294173 | G11: Suma końcowa | H11: 43339511
A13: Zysk netto RZiS | B13: =B6+B4+B8-B5-B7-B9-B10 -> 324636.34 | G13: Zysk netto RZiS | H13: =H6+H4+H8-H5-H7-H9-H10 -> 342288.94
A14: Per TB | B14: =SUMIF('2025 ZOiS'!D:D,"Wynikowe",'2025 ZOiS'!Q:Q) -> -324636.34 | G14: Per TB | H14: =SUMIF('2024 ZOiS'!D:D,"Wynikowe",'2024 ZOiS'!Q:Q) -> 342288.94
B15: =B13+B14 -> -1.6647391e-08 | H15: =H13-H14 -> -9.0803951e-09

Sheet 25 RZiS Zmapowane P+
A1: Rodzaj1 | B1: Rodzaj2 | C1: Rodzaj3 | D1: Numer konta | E1: Nazwa konta | F1: Rodzaj konta (bilansowe/wynikowe) | G1: 2025-01 | H1: 2025-02 | I1: 2025-03 | J1: 2025-04 | K1: 2025-05 | L1: 2025-06 | M1: 2025-07 | N1: 2025-08 | O1: 2025-09 | P1: 2025-10 | Q1: 2025-11 | R1: 2025-12 | S1: 2025 | T1: -1
A2: =IF(ISNUMBER(SEARCH("przychody",B2)),"Przychody","Koszty") -> Przychody | B2: A. Przychody netto ze sprzedaży i zrównane z nimi, w tym: | C2: I. Przychody netto ze sprzedaży produktów | D2: 45510000 | E2: 45510000 Prowizja Cost+ | F2: Wynikowe | G2: 1877205 | H2: 1844622 | I2: 1802379 | J2: 1430181 | K2: 1741817 | L2: 1686073 | M2: 1733363 | N2: 1733363 | O2: 1733363 | P2: 1711660 | Q2: 1711660 | R2: 3177425 | S2: =SUM(_25[[#This Row],[2025-01]:[2025-12]]) -> 22183111
A3: =IF(ISNUMBER(SEARCH("przychody",B3)),"Przychody","Koszty") -> Przychody | B3: A. Przychody netto ze sprzedaży i zrównane z nimi, w tym: | C3: I. Przychody netto ze sprzedaży produktów | D3: 44000000 | E3: 44000000 Przychód operacyjny - opłata za konosament | F3: Wynikowe | G3: 0 | H3: 0 | I3: 0 | J3: 0 | K3: 0 | L3: 0 | M3: 0 | N3: 0 | O3: 0 | P3: 0 | Q3: 0 | R3: 0 | S3: =SUM(_25[[#This Row],[2025-01]:[2025-12]]) -> 0
A4: =IF(ISNUMBER(SEARCH("przychody",B4)),"Przychody","Koszty") -> Przychody | B4: A. Przychody netto ze sprzedaży i zrównane z nimi, w tym: | C4: I. Przychody netto ze sprzedaży produktów | D4: 44000005 | E4: 44000005 Przychód operacyjny - opłata dokumentacyjna EXP | F4: Wynikowe | G4: 0 | H4: 0 | I4: 0 | J4: 0 | K4: 0 | L4: 0 | M4: 0 | N4: 0 | O4: 0 | P4: 0 | Q4: 0 | R4: 0 | S4: =SUM(_25[[#This Row],[2025-01]:[2025-12]]) -> 0
A5: =IF(ISNUMBER(SEARCH("przychody",B5)),"Przychody","Koszty") -> Przychody | B5: A. Przychody netto ze sprzedaży i zrównane z nimi, w tym: | C5: I. Przychody netto ze sprzedaży produktów | D5: 44006000 | E5: 44006000 Przychód operacyjny - korekta manifestu | F5: Wynikowe | G5: 0 | H5: 0 | I5: 0 | J5: 0 | K5: 0 | L5: 0 | M5: 0 | N5: 0 | O5: 0 | P5: 0 | Q5: 0 | R5: 0 | S5: =SUM(_25[[#This Row],[2025-01]:[2025-12]]) -> 0
A6: =IF(ISNUMBER(SEARCH("przychody",B6)),"Przychody","Koszty") -> Koszty | B6: B. Koszty działalności operacyjnej | C6: I. Amortyzacja | D6: 61000000 | E6: 61000000 Oprogramowanie i licencje IT - Amortyzacja | F6: Wynikowe | G6: 926.5 | H6: 926.5 | I6: 926.5 | J6: 926.5 | K6: 926.5 | L6: 926.5 | M6: 926.5 | N6: 926.5 | O6: 926.5 | P6: 926.5 | Q6: 926.5 | R6: 926.5 | S6: =SUM(_25[[#This Row],[2025-01]:[2025-12]]) -> 11118
A7: =IF(ISNUMBER(SEARCH("przychody",B7)),"Przychody","Koszty") -> Koszty | B7: B. Koszty działalności operacyjnej | C7: =C6 -> I. Amortyzacja | D7: 61502000 | E7: 61502000 Budynki - Amortyzacja | F7: Wynikowe | G7: 17326.2 | H7: 17326.2 | I7: 17326.21 | J7: 17326.2 | K7: 17326.2 | L7: 17326.2 | M7: 17326.2 | N7: 17326.2 | O7: 17326.21 | P7: 17326.2 | Q7: 17326.2 | R7: 17326.2 | S7: =SUM(_25[[#This Row],[2025-01]:[2025-12]]) -> 207914.42
A8: =IF(ISNUMBER(SEARCH("przychody",B8)),"Przychody","Koszty") -> Koszty | B8: B. Koszty działalności operacyjnej | C8: =C7 -> I. Amortyzacja | D8: 61504000 | E8: 61504000 Nakłady w obcych środkach trwał - Amortyzacja | F8: Wynikowe | G8: 313.46 | H8: 313.45 | I8: 313.46 | J8: 313.46 | K8: 6769.34 | L8: 1604.64 | M8: 1604.64 | N8: 1604.63 | O8: 1604.64 | P8: 1604.63 | Q8: 1604.63 | R8: 1604.64 | S8: =SUM(_25[[#This Row],[2025-01]:[2025-12]]) -> 19255.62
A9: =IF(ISNUMBER(SEARCH("przychody",B9)),"Przychody","Koszty") -> Koszty | B9: B. Koszty działalności operacyjnej | C9: =C8 -> I. Amortyzacja | D9: 61508000 | E9: 61508000 Komputery i sprzęt IT - Amortyzacja | F9: Wynikowe | G9: 10218.3 | H9: 8464.79 | I9: 11588.15 | J9: 24240.21 | K9: 459 | L9: 0 | M9: 16357.33 | N9: 579 | O9: 4146.34 | P9: 12895.39 | Q9: 2065.04 | R9: 11369.44 | S9: =SUM(_25[[#This Row],[2025-01]:[2025-12]]) -> 102382.99
A10: =IF(ISNUMBER(SEARCH("przychody",B10)),"Przychody","Koszty") -> Koszty | B10: B. Koszty działalności operacyjnej | C10: =C9 -> I. Amortyzacja | D10: 61512000 | E10: 61512000 Meble - Amortyzacja | F10: Wynikowe | G10: 965.04 | H10: 1635.1 | I10: 3421.14 | J10: 18409.02 | K10: 1749.81 | L10: 1749.8 | M10: 3748.51 | N10: 1749.81 | O10: 1749.8 | P10: 4649.8 | Q10: 1749.8 | R10: 816.98 | S10: =SUM(_25[[#This Row],[2025-01]:[2025-12]]) -> 42394.61
A11: =IF(ISNUMBER(SEARCH("przychody",B11)),"Przychody","Koszty") -> Koszty | B11: B. Koszty działalności operacyjnej | C11: =C10 -> I. Amortyzacja | D11: 61518000 | E11: 61518000 Samochody - Amortyzacja | F11: Wynikowe | G11: 16100.98 | H11: 16101 | I11: 16100.99 | J11: 13559.44 | K11: 8113.52 | L11: 6162.77 | M11: 6162.45 | N11: 6162.46 | O11: 6162.48 | P11: 6162.47 | Q11: 6162.46 | R11: 6162.46 | S11: =SUM(_25[[#This Row],[2025-01]:[2025-12]]) -> 113113.48
A12: =IF(ISNUMBER(SEARCH("przychody",B12)),"Przychody","Koszty") -> Koszty | B12: B. Koszty działalności operacyjnej | C12: II. Zużycie materiałów i energii | D12: 58502000 | E12: 58502000 Energia cieplna | F12: Wynikowe | G12: 4570.88 | H12: 4099.71 | I12: 4862.37 | J12: 4987.16 | K12: 4558.32 | L12: 4744.18 | M12: 8241.36 | N12: 5397.11 | O12: 5554.37 | P12: 4288.71 | Q12: 5699.53 | R12: 5270.55 | S12: =SUM(_25[[#This Row],[2025-01]:[2025-12]]) -> 62274.25
A13: =IF(ISNUMBER(SEARCH("przychody",B13)),"Przychody","Koszty") -> Koszty | B13: B. Koszty działalności operacyjnej | C13: =C12 -> II. Zużycie materiałów i energii | D13: 58502001 | E13: 58502001 Woda | F13: Wynikowe | G13: 928.32 | H13: 1511.16 | I13: 1199.06 | J13: 1726 | K13: 844.52 | L13: 966.37 | M13: -148.66 | N13: 1216.82 | O13: 1255.33 | P13: 1280.2 | Q13: 814.72 | R13: 1139.18 | S13: =SUM(_25[[#This Row],[2025-01]:[2025-12]]) -> 12733.02
A14: =IF(ISNUMBER(SEARCH("przychody",B14)),"Przychody","Koszty") -> Koszty | B14: B. Koszty działalności operacyjnej | C14: =C13 -> II. Zużycie materiałów i energii | D14: 58502002 | E14: 58502002 Energia elektryczna | F14: Wynikowe | G14: 872.32 | H14: 5284.06 | I14: 2746.11 | J14: 10086.23 | K14: 4947.58 | L14: 1981.79 | M14: 7500.2 | N14: 4769.2 | O14: 5214.36 | P14: 4125.63 | Q14: 5412.44 | R14: 4570.41 | S14: =SUM(_25[[#This Row],[2025-01]:[2025-12]]) -> 57510.33
A15: =IF(ISNUMBER(SEARCH("przychody",B15)),"Przychody","Koszty") -> Koszty | B15: B. Koszty działalności operacyjnej | C15: =C14 -> II. Zużycie materiałów i energii | D15: 58508000 | E15: 58508000 Materiały biurowe | F15: Wynikowe | G15: 3888.21 | H15: 8046.53 | I15: 5925.51 | J15: 10591.79 | K15: 3481.33 | L15: 5980.06 | M15: 5804.8 | N15: 2975.62 | O15: 28115.14 | P15: 3405.81 | Q15: 26075.62 | R15: 5416.46 | S15: =SUM(_25[[#This Row],[2025-01]:[2025-12]]) -> 109706.88
A16: =IF(ISNUMBER(SEARCH("przychody",B16)),"Przychody","Koszty") -> Koszty | B16: B. Koszty działalności operacyjnej | C16: =C15 -> II. Zużycie materiałów i energii | D16: 58552002 | E16: 58552002 Samochody - paliwo 75% | F16: Wynikowe | G16: 0 | H16: 13424.82 | I16: 13326.33 | J16: 7673.38 | K16: 3423.14 | L16: 6973.6 | M16: 9473.02 | N16: 6485.65 | O16: 11046.43 | P16: 8643.36 | Q16: 13399.64 | R16: 6568.65 | S16: =SUM(_25[[#This Row],[2025-01]:[2025-12]]) -> 100438.02
A17: =IF(ISNUMBER(SEARCH("przychody",B17)),"Przychody","Koszty") -> Koszty | B17: B. Koszty działalności operacyjnej | C17: =C16 -> II. Zużycie materiałów i energii | D17: 58552003 | E17: 58552003 Samochody - paliwo 25% | F17: Wynikowe | G17: 0 | H17: 4474.94 | I17: 4442.11 | J17: 2557.79 | K17: 1141.04 | L17: 2324.52 | M17: 3157.65 | N17: 2161.89 | O17: 3701.64 | P17: 2861.56 | Q17: 4466.53 | R17: 2189.54 | S17: =SUM(_25[[#This Row],[2025-01]:[2025-12]]) -> 33479.21
A18: =IF(ISNUMBER(SEARCH("przychody",B18)),"Przychody","Koszty") -> Koszty | B18: B. Koszty działalności operacyjnej | C18: =C17 -> II. Zużycie materiałów i energii | D18: 58552005 | E18: 58552005 Samochody - eksploatacja 75% | F18: Wynikowe | G18: 6578.88 | H18: 7894.13 | I18: 4979.25 | J18: 5105.19 | K18: 7660.35 | L18: 7622.12 | M18: 6784.33 | N18: 3820.27 | O18: 4466.23 | P18: 13632.85 | Q18: 6401.26 | R18: 9230.72 | S18: =SUM(_25[[#This Row],[2025-01]:[2025-12]]) -> 84175.58
A19: =IF(ISNUMBER(SEARCH("przychody",B19)),"Przychody","Koszty") -> Koszty | B19: B. Koszty działalności operacyjnej | C19: =C18 -> II. Zużycie materiałów i energii | D19: 58552025 | E19: 58552025 Samochody - eksploatacja 25% | F19: Wynikowe | G19: 2138.84 | H19: 2975.96 | I19: 1659.72 | J19: 1701.74 | K19: 2563.43 | L19: 2740.7 | M19: 2261.41 | N19: 1273.41 | O19: 1554.23 | P19: 4895.93 | Q19: 2133.71 | R19: 3138.34 | S19: =SUM(_25[[#This Row],[2025-01]:[2025-12]]) -> 29037.42
A20: =IF(ISNUMBER(SEARCH("przychody",B20)),"Przychody","Koszty") -> Koszty | B20: B. Koszty działalności operacyjnej | C20: III. Usługi obce | D20: 53080000 | E20: 53080000 Koszt operacyjny - pozostałe koszty na termin mors | F20: Wynikowe | G20: 22.83 | H20: 0 | I20: 0 | J20: 0 | K20: 0 | L20: 0 | M20: 0 | N20: 0 | O20: 0 | P20: 0 | Q20: 0 | R20: 0 | S20: =SUM(_25[[#This Row],[2025-01]:[2025-12]]) -> 22.83
A21: =IF(ISNUMBER(SEARCH("przychody",B21)),"Przychody","Koszty") -> Koszty | B21: B. Koszty działalności operacyjnej | C21: =C20 -> III. Usługi obce | D21: 58500000 | E21: 58500000 Wynajęcie biura | F21: Wynikowe | G21: 43618.17 | H21: 6220.09 | I21: 65139.98 | J21: 37383.83 | K21: 37738.79 | L21: 36686.81 | M21: 36794.1 | N21: 36392.29 | O21: 36321.9 | P21: 37209.57 | Q21: 37838.26 | R21: 36875.41 | S21: =SUM(_25[[#This Row],[2025-01]:[2025-12]]) -> 448219.2
A22: =IF(ISNUMBER(SEARCH("przychody",B22)),"Przychody","Koszty") -> Koszty | B22: B. Koszty działalności operacyjnej | C22: =C21 -> III. Usługi obce | D22: 58500010 | E22: 58500010 Wynajecie parkingu | F22: Wynikowe | G22: 8194.97 | H22: 2573.17 | I22: 11589.29 | J22: 9158.13 | K22: 9058.49 | L22: 7898.77 | M22: 8730.43 | N22: 8932.14 | O22: 8810.97 | P22: 8314.82 | Q22: 9074.49 | R22: 8581.96 | S22: =SUM(_25[[#This Row],[2025-01]:[2025-12]]) -> 100917.63
A23: =IF(ISNUMBER(SEARCH("przychody",B23)),"Przychody","Koszty") -> Koszty | B23: B. Koszty działalności operacyjnej | C23: =C22 -> III. Usługi obce | D23: 58502003 | E23: 58502003 Ubezpieczenie biura | F23: Wynikowe | G23: 1876.68 | H23: 1894.43 | I23: 1894.43 | J23: 2340.5 | K23: 2102.49 | L23: 2102.49 | M23: 2102.49 | N23: 2102.49 | O23: 2102.49 | P23: 2102.49 | Q23: 2102.49 | R23: 2102.49 | S23: =SUM(_25[[#This Row],[2025-01]:[2025-12]]) -> 24825.96
A24: =IF(ISNUMBER(SEARCH("przychody",B24)),"Przychody","Koszty") -> Koszty | B24: B. Koszty działalności operacyjnej | C24: =C23 -> III. Usługi obce | D24: 58504000 | E24: 58504000 Naprawa biura | F24: Wynikowe | G24: 2588.68 | H24: 1438.68 | I24: 1438.68 | J24: 1984.98 | K24: 2770.21 | L24: 3070.21 | M24: 1570.21 | N24: 1570.21 | O24: 1570.21 | P24: 1570.21 | Q24: 1570.21 | R24: 1570.21 | S24: =SUM(_25[[#This Row],[2025-01]:[2025-12]]) -> 22712.7
A25: =IF(ISNUMBER(SEARCH("przychody",B25)),"Przychody","Koszty") -> Koszty | B25: B. Koszty działalności operacyjnej | C25: =C24 -> III. Usługi obce | D25: 58504001 | E25: 58504001 Eksploatacja biura | F25: Wynikowe | G25: 14370.53 | H25: 3620.96 | I25: 18678.36 | J25: 11848.6 | K25: 20305.13 | L25: 10875.58 | M25: 14371.05 | N25: 10492.94 | O25: 13155.2 | P25: 14632.73 | Q25: 12723.92 | R25: 12812.35 | S25: =SUM(_25[[#This Row],[2025-01]:[2025-12]]) -> 157887.35
A26: =IF(ISNUMBER(SEARCH("przychody",B26)),"Przychody","Koszty") -> Koszty | B26: B. Koszty działalności operacyjnej | C26: =C25 -> III. Usługi obce | D26: 58504002 | E26: 58504002 Sprzątanie biura | F26: Wynikowe | G26: 8520.75 | H26: 1218.86 | I26: 8818.86 | J26: 8292.7 | K26: 6702.42 | L26: 8542.42 | M26: 9100.53 | N26: 8504.31 | O26: 9100.53 | P26: 8504.31 | Q26: 8802.42 | R26: 16700.53 | S26: =SUM(_25[[#This Row],[2025-01]:[2025-12]]) -> 102808.64
A27: =IF(ISNUMBER(SEARCH("przychody",B27)),"Przychody","Koszty") -> Koszty | B27: B. Koszty działalności operacyjnej | C27: IV. Podatki i opłaty | D27: 58506000 | E27: 58506000 Opłaty prawne | F27: Wynikowe | G27: 0 | H27: 33385 | I27: 1 | J27: 0 | K27: 0 | L27: 3 | M27: 350 | N27: 1 | O27: 192 | P27: 900 | Q27: -900 | R27: 0 | S27: =SUM(_25[[#This Row],[2025-01]:[2025-12]]) -> 33932
A28: =IF(ISNUMBER(SEARCH("przychody",B28)),"Przychody","Koszty") -> Koszty | B28: B. Koszty działalności operacyjnej | C28: III. Usługi obce | D28: 58506001 | E28: 58506001 Usługi prawnicze | F28: Wynikowe | G28: 28945.74 | H28: 4580 | I28: 9520 | J28: 4100 | K28: 3500 | L28: 3500 | M28: 3980 | N28: 3500 | O28: 3500 | P28: 3500 | Q28: 4160 | R28: 3740 | S28: =SUM(_25[[#This Row],[2025-01]:[2025-12]]) -> 76525.74
A29: =IF(ISNUMBER(SEARCH("przychody",B29)),"Przychody","Koszty") -> Koszty | B29: B. Koszty działalności operacyjnej | C29: =C28 -> III. Usługi obce | D29: 58506003 | E29: 58506003 Usługi audytorskie | F29: Wynikowe | G29: 0 | H29: 12267.4 | I29: 12302.38 | J29: 0 | K29: 0 | L29: 0 | M29: 0 | N29: 0 | O29: 5020 | P29: 0 | Q29: 0 | R29: 24800 | S29: =SUM(_25[[#This Row],[2025-01]:[2025-12]]) -> 54389.78
A30: =IF(ISNUMBER(SEARCH("przychody",B30)),"Przychody","Koszty") -> Koszty | B30: B. Koszty działalności operacyjnej | C30: =C29 -> III. Usługi obce | D30: 58506004 | E30: 58506004 Usługi doradztwa podatkowego | F30: Wynikowe | G30: 0 | H30: 0 | I30: 0 | J30: 41544.95 | K30: 0 | L30: 0 | M30: 80044.84 | N30: 0 | O30: 24470.6 | P30: 0 | Q30: 22658.13 | R30: 15496.6 | S30: =SUM(_25[[#This Row],[2025-01]:[2025-12]]) -> 184215.12
A31: =IF(ISNUMBER(SEARCH("przychody",B31)),"Przychody","Koszty") -> Koszty | B31: B. Koszty działalności operacyjnej | C31: =C30 -> III. Usługi obce | D31: 58506006 | E31: 58506006 Usługi rekrutacyjne | F31: Wynikowe | G31: 6232.2 | H31: 0 | I31: 0 | J31: 0 | K31: 0 | L31: 0 | M31: 0 | N31: 499 | O31: 0 | P31: 0 | Q31: 0 | R31: 0 | S31: =SUM(_25[[#This Row],[2025-01]:[2025-12]]) -> 6731.2
A32: =IF(ISNUMBER(SEARCH("przychody",B32)),"Przychody","Koszty") -> Koszty | B32: B. Koszty działalności operacyjnej | C32: =C31 -> III. Usługi obce | D32: 58507000 | E32: 58507000 Pozostałe usługi | F32: Wynikowe | G32: 2011 | H32: 1985.88 | I32: 1529.17 | J32: 1038.8 | K32: 6022.8 | L32: 4702.4 | M32: 25.95 | N32: 866.4 | O32: 3533.8 | P32: 1863.85 | Q32: 312.46 | R32: 2305.9 | S32: =SUM(_25[[#This Row],[2025-01]:[2025-12]]) -> 26198.41
A33: =IF(ISNUMBER(SEARCH("przychody",B33)),"Przychody","Koszty") -> Koszty | B33: B. Koszty działalności operacyjnej | C33: =C32 -> III. Usługi obce | D33: 58507001 | E33: 58507001 Archiwizacja | F33: Wynikowe | G33: 0 | H33: 0 | I33: 1755 | J33: 0 | K33: 0 | L33: 0 | M33: 0 | N33: 0 | O33: 0 | P33: 147 | Q33: 0 | R33: 0 | S33: =SUM(_25[[#This Row],[2025-01]:[2025-12]]) -> 1902
A34: =IF(ISNUMBER(SEARCH("przychody",B34)),"Przychody","Koszty") -> Koszty | B34: B. Koszty działalności operacyjnej | C34: =C33 -> III. Usługi obce | D34: 58521000 | E34: 58521000 Telefony stacjonarne | F34: Wynikowe | G34: 5551.22 | H34: 4237.84 | I34: 4189.37 | J34: 4301.69 | K34: 4306.5 | L34: 4199.25 | M34: 4188.08 | N34: 4320.84 | O34: 4167.29 | P34: 4213.27 | Q34: 4302.22 | R34: 4548.96 | S34: =SUM(_25[[#This Row],[2025-01]:[2025-12]]) -> 52526.53
A35: =IF(ISNUMBER(SEARCH("przychody",B35)),"Przychody","Koszty") -> Koszty | B35: B. Koszty działalności operacyjnej | C35: =C34 -> III. Usługi obce | D35: 58522000 | E35: 58522000 Telefony komórkowe | F35: Wynikowe | G35: 1882.58 | H35: 3244.02 | I35: 1787.78 | J35: 1568.18 | K35: 1232.58 | L35: 1224.02 | M35: 360.22 | N35: 2063.55 | O35: 1459.83 | P35: 1478.4 | Q35: 1142.82 | R35: 1147.79 | S35: =SUM(_25[[#This Row],[2025-01]:[2025-12]]) -> 18591.77
A36: =IF(ISNUMBER(SEARCH("przychody",B36)),"Przychody","Koszty") -> Koszty | B36: B. Koszty działalności operacyjnej | C36: =C35 -> III. Usługi obce | D36: 58525000 | E36: 58525000 Internet | F36: Wynikowe | G36: 1950 | H36: 0 | I36: 4519.99 | J36: 2329.99 | K36: 2329.99 | L36: 2190 | M36: 2190 | N36: 2190 | O36: 2190 | P36: 2190 | Q36: 2190 | R36: 2430 | S36: =SUM(_25[[#This Row],[2025-01]:[2025-12]]) -> 26699.97
A37: =IF(ISNUMBER(SEARCH("przychody",B37)),"Przychody","Koszty") -> Koszty | B37: B. Koszty działalności operacyjnej | C37: =C36 -> III. Usługi obce | D37: 58527000 | E37: 58527000 Usługi pocztowe i kurierskie | F37: Wynikowe | G37: 1483.23 | H37: 2603.43 | I37: -1191.97 | J37: 1153.83 | K37: 1127.33 | L37: 1485.05 | M37: 2146.4 | N37: 1513.85 | O37: 1259.56 | P37: 1010.22 | Q37: 1281.68 | R37: 5077.31 | S37: =SUM(_25[[#This Row],[2025-01]:[2025-12]]) -> 18949.92
A38: =IF(ISNUMBER(SEARCH("przychody",B38)),"Przychody","Koszty") -> Koszty | B38: B. Koszty działalności operacyjnej | C38: =C37 -> III. Usługi obce | D38: 58530200 | E38: 58530200 Koszty oprogramowania | F38: Wynikowe | G38: 11019.62 | H38: 8006.1 | I38: 7596.1 | J38: 13813.1 | K38: 7546.1 | L38: 7776.1 | M38: 7643.1 | N38: 6511.1 | O38: 6971.1 | P38: 10946.1 | Q38: 8639.1 | R38: 3006 | S38: =SUM(_25[[#This Row],[2025-01]:[2025-12]]) -> 99473.62
A39: =IF(ISNUMBER(SEARCH("przychody",B39)),"Przychody","Koszty") -> Koszty | B39: B. Koszty działalności operacyjnej | C39: =C38 -> III. Usługi obce | D39: 58530500 | E39: 58530500 Usługi konsultingowe IT | F39: Wynikowe | G39: 3390 | H39: 4580 | I39: 4050 | J39: 5530 | K39: 4170 | L39: 3690 | M39: 4340 | N39: 2140 | O39: 4060 | P39: 5730 | Q39: 10320.2 | R39: 5600 | S39: =SUM(_25[[#This Row],[2025-01]:[2025-12]]) -> 57600.2
A40: =IF(ISNUMBER(SEARCH("przychody",B40)),"Przychody","Koszty") -> Koszty | B40: B. Koszty działalności operacyjnej | C40: =C39 -> III. Usługi obce | D40: 58530700 | E40: 58530700 Pozostałe koszty IT | F40: Wynikowe | G40: 207.45 | H40: 0 | I40: 0 | J40: 1179.2 | K40: 14.7 | L40: 3210.27 | M40: 1121.43 | N40: 0 | O40: 0 | P40: 868.34 | Q40: 926.86 | R40: 0 | S40: =SUM(_25[[#This Row],[2025-01]:[2025-12]]) -> 7528.25
...

Sheet 25 RZiS Zmapowane
A1: Rodzaj1 | B1: Rodzaj2 | C1: Rodzaj3 | D1: Numer konta | E1: Nazwa konta | F1: Rodzaj konta (bilansowe/wynikowe) | G1: 2025/Jan | H1: 2025/Feb | I1: 2025/Mar | J1: 2025/Apr | K1: 2025/May | L1: 2025/Jun | M1: 2025/Jul | N1: 2025/Aug | O1: 2025/Sep | P1: 2025/Oct | Q1: 2025/Nov | R1: 2025/Dec
A2: =IF(ISNUMBER(SEARCH("przychody",C2)),"Przychody","Koszty") -> Przychody | B2: A. Przychody netto ze sprzedaży i zrównane z nimi, w tym: | C2: I. Przychody netto ze sprzedaży produktów | D2: 45510000 | E2: 45510000 Prowizja Cost+ | F2: Wynikowe | G2: -1877205 | H2: -1844622 | I2: -1802379 | J2: -1430181 | K2: -1741817 | L2: -1686073 | M2: -1733363 | N2: -1733363 | O2: -1733363 | P2: -1711660 | Q2: -1711660 | R2: -3177425
A3: =IF(ISNUMBER(SEARCH("przychody",C3)),"Przychody","Koszty") -> Przychody | B3: A. Przychody netto ze sprzedaży i zrównane z nimi, w tym: | C3: I. Przychody netto ze sprzedaży produktów | D3: 44000000 | E3: 44000000 Przychód operacyjny - opłata za konosament | F3: Wynikowe | G3: 0 | H3: 0 | I3: 0 | J3: 0 | K3: 0 | L3: 0 | M3: 0 | N3: 0 | O3: 0 | P3: 0 | Q3: 0 | R3: 0
A4: =IF(ISNUMBER(SEARCH("przychody",C4)),"Przychody","Koszty") -> Przychody | B4: A. Przychody netto ze sprzedaży i zrównane z nimi, w tym: | C4: I. Przychody netto ze sprzedaży produktów | D4: 44000005 | E4: 44000005 Przychód operacyjny - opłata dokumentacyjna EXP | F4: Wynikowe | G4: 0 | H4: 0 | I4: 0 | J4: 0 | K4: 0 | L4: 0 | M4: 0 | N4: 0 | O4: 0 | P4: 0 | Q4: 0 | R4: 0
A5: =IF(ISNUMBER(SEARCH("przychody",C5)),"Przychody","Koszty") -> Przychody | B5: A. Przychody netto ze sprzedaży i zrównane z nimi, w tym: | C5: I. Przychody netto ze sprzedaży produktów | D5: 44006000 | E5: 44006000 Przychód operacyjny - korekta manifestu | F5: Wynikowe | G5: 0 | H5: 0 | I5: 0 | J5: 0 | K5: 0 | L5: 0 | M5: 0 | N5: 0 | O5: 0 | P5: 0 | Q5: 0 | R5: 0
A6: =IF(ISNUMBER(SEARCH("przychody",C6)),"Przychody","Koszty") -> Koszty | B6: B. Koszty działalności operacyjnej | C6: I. Amortyzacja | D6: 61000000 | E6: 61000000 Oprogramowanie i licencje IT - Amortyzacja | F6: Wynikowe | G6: 926.5 | H6: 926.5 | I6: 926.5 | J6: 926.5 | K6: 926.5 | L6: 926.5 | M6: 926.5 | N6: 926.5 | O6: 926.5 | P6: 926.5 | Q6: 926.5 | R6: 926.5
A7: =IF(ISNUMBER(SEARCH("przychody",C7)),"Przychody","Koszty") -> Koszty | B7: B. Koszty działalności operacyjnej | C7: =C6 -> I. Amortyzacja | D7: 61502000 | E7: 61502000 Budynki - Amortyzacja | F7: Wynikowe | G7: 17326.2 | H7: 17326.2 | I7: 17326.21 | J7: 17326.2 | K7: 17326.2 | L7: 17326.2 | M7: 17326.2 | N7: 17326.2 | O7: 17326.21 | P7: 17326.2 | Q7: 17326.2 | R7: 17326.2
A8: =IF(ISNUMBER(SEARCH("przychody",C8)),"Przychody","Koszty") -> Koszty | B8: B. Koszty działalności operacyjnej | C8: =C7 -> I. Amortyzacja | D8: 61504000 | E8: 61504000 Nakłady w obcych środkach trwał - Amortyzacja | F8: Wynikowe | G8: 313.46 | H8: 313.45 | I8: 313.46 | J8: 313.46 | K8: 6769.34 | L8: 1604.64 | M8: 1604.64 | N8: 1604.63 | O8: 1604.64 | P8: 1604.63 | Q8: 1604.63 | R8: 1604.64
A9: =IF(ISNUMBER(SEARCH("przychody",C9)),"Przychody","Koszty") -> Koszty | B9: B. Koszty działalności operacyjnej | C9: =C8 -> I. Amortyzacja | D9: 61508000 | E9: 61508000 Komputery i sprzęt IT - Amortyzacja | F9: Wynikowe | G9: 10218.3 | H9: 8464.79 | I9: 11588.15 | J9: 24240.21 | K9: 459 | L9: 0 | M9: 16357.33 | N9: 579 | O9: 4146.34 | P9: 12895.39 | Q9: 2065.04 | R9: 11369.44
A10: =IF(ISNUMBER(SEARCH("przychody",C10)),"Przychody","Koszty") -> Koszty | B10: B. Koszty działalności operacyjnej | C10: =C9 -> I. Amortyzacja | D10: 61512000 | E10: 61512000 Meble - Amortyzacja | F10: Wynikowe | G10: 965.04 | H10: 1635.1 | I10: 3421.14 | J10: 18409.02 | K10: 1749.81 | L10: 1749.8 | M10: 3748.51 | N10: 1749.81 | O10: 1749.8 | P10: 4649.8 | Q10: 1749.8 | R10: 816.98
A11: =IF(ISNUMBER(SEARCH("przychody",C11)),"Przychody","Koszty") -> Koszty | B11: B. Koszty działalności operacyjnej | C11: =C10 -> I. Amortyzacja | D11: 61518000 | E11: 61518000 Samochody - Amortyzacja | F11: Wynikowe | G11: 16100.98 | H11: 16101 | I11: 16100.99 | J11: 13559.44 | K11: 8113.52 | L11: 6162.77 | M11: 6162.45 | N11: 6162.46 | O11: 6162.48 | P11: 6162.47 | Q11: 6162.46 | R11: 6162.46
A12: =IF(ISNUMBER(SEARCH("przychody",C12)),"Przychody","Koszty") -> Koszty | B12: B. Koszty działalności operacyjnej | C12: II. Zużycie materiałów i energii | D12: 58502000 | E12: 58502000 Energia cieplna | F12: Wynikowe | G12: 4570.88 | H12: 4099.71 | I12: 4862.37 | J12: 4987.16 | K12: 4558.32 | L12: 4744.18 | M12: 8241.36 | N12: 5397.11 | O12: 5554.37 | P12: 4288.71 | Q12: 5699.53 | R12: 5270.55
A13: =IF(ISNUMBER(SEARCH("przychody",C13)),"Przychody","Koszty") -> Koszty | B13: B. Koszty działalności operacyjnej | C13: =C12 -> II. Zużycie materiałów i energii | D13: 58502001 | E13: 58502001 Woda | F13: Wynikowe | G13: 928.32 | H13: 1511.16 | I13: 1199.06 | J13: 1726 | K13: 844.52 | L13: 966.37 | M13: -148.66 | N13: 1216.82 | O13: 1255.33 | P13: 1280.2 | Q13: 814.72 | R13: 1139.18
A14: =IF(ISNUMBER(SEARCH("przychody",C14)),"Przychody","Koszty") -> Koszty | B14: B. Koszty działalności operacyjnej | C14: =C13 -> II. Zużycie materiałów i energii | D14: 58502002 | E14: 58502002 Energia elektryczna | F14: Wynikowe | G14: 872.32 | H14: 5284.06 | I14: 2746.11 | J14: 10086.23 | K14: 4947.58 | L14: 1981.79 | M14: 7500.2 | N14: 4769.2 | O14: 5214.36 | P14: 4125.63 | Q14: 5412.44 | R14: 4570.41
A15: =IF(ISNUMBER(SEARCH("przychody",C15)),"Przychody","Koszty") -> Koszty | B15: B. Koszty działalności operacyjnej | C15: =C14 -> II. Zużycie materiałów i energii | D15: 58508000 | E15: 58508000 Materiały biurowe | F15: Wynikowe | G15: 3888.21 | H15: 8046.53 | I15: 5925.51 | J15: 10591.79 | K15: 3481.33 | L15: 5980.06 | M15: 5804.8 | N15: 2975.62 | O15: 28115.14 | P15: 3405.81 | Q15: 26075.62 | R15: 5416.46
A16: =IF(ISNUMBER(SEARCH("przychody",C16)),"Przychody","Koszty") -> Koszty | B16: B. Koszty działalności operacyjnej | C16: =C15 -> II. Zużycie materiałów i energii | D16: 58552002 | E16: 58552002 Samochody - paliwo 75% | F16: Wynikowe | G16: 0 | H16: 13424.82 | I16: 13326.33 | J16: 7673.38 | K16: 3423.14 | L16: 6973.6 | M16: 9473.02 | N16: 6485.65 | O16: 11046.43 | P16: 8643.36 | Q16: 13399.64 | R16: 6568.65
A17: =IF(ISNUMBER(SEARCH("przychody",C17)),"Przychody","Koszty") -> Koszty | B17: B. Koszty działalności operacyjnej | C17: =C16 -> II. Zużycie materiałów i energii | D17: 58552003 | E17: 58552003 Samochody - paliwo 25% | F17: Wynikowe | G17: 0 | H17: 4474.94 | I17: 4442.11 | J17: 2557.79 | K17: 1141.04 | L17: 2324.52 | M17: 3157.65 | N17: 2161.89 | O17: 3701.64 | P17: 2861.56 | Q17: 4466.53 | R17: 2189.54
A18: =IF(ISNUMBER(SEARCH("przychody",C18)),"Przychody","Koszty") -> Koszty | B18: B. Koszty działalności operacyjnej | C18: =C17 -> II. Zużycie materiałów i energii | D18: 58552005 | E18: 58552005 Samochody - eksploatacja 75% | F18: Wynikowe | G18: 6578.88 | H18: 7894.13 | I18: 4979.25 | J18: 5105.19 | K18: 7660.35 | L18: 7622.12 | M18: 6784.33 | N18: 3820.27 | O18: 4466.23 | P18: 13632.85 | Q18: 6401.26 | R18: 9230.72
A19: =IF(ISNUMBER(SEARCH("przychody",C19)),"Przychody","Koszty") -> Koszty | B19: B. Koszty działalności operacyjnej | C19: =C18 -> II. Zużycie materiałów i energii | D19: 58552025 | E19: 58552025 Samochody - eksploatacja 25% | F19: Wynikowe | G19: 2138.84 | H19: 2975.96 | I19: 1659.72 | J19: 1701.74 | K19: 2563.43 | L19: 2740.7 | M19: 2261.41 | N19: 1273.41 | O19: 1554.23 | P19: 4895.93 | Q19: 2133.71 | R19: 3138.34
A20: =IF(ISNUMBER(SEARCH("przychody",C20)),"Przychody","Koszty") -> Koszty | B20: B. Koszty działalności operacyjnej | C20: III. Usługi obce | D20: 53080000 | E20: 53080000 Koszt operacyjny - pozostałe koszty na termin mors | F20: Wynikowe | G20: 22.83 | H20: 0 | I20: 0 | J20: 0 | K20: 0 | L20: 0 | M20: 0 | N20: 0 | O20: 0 | P20: 0 | Q20: 0 | R20: 0
A21: =IF(ISNUMBER(SEARCH("przychody",C21)),"Przychody","Koszty") -> Koszty | B21: B. Koszty działalności operacyjnej | C21: =C20 -> III. Usługi obce | D21: 58500000 | E21: 58500000 Wynajęcie biura | F21: Wynikowe | G21: 43618.17 | H21: 6220.09 | I21: 65139.98 | J21: 37383.83 | K21: 37738.79 | L21: 36686.81 | M21: 36794.1 | N21: 36392.29 | O21: 36321.9 | P21: 37209.57 | Q21: 37838.26 | R21: 36875.41
A22: =IF(ISNUMBER(SEARCH("przychody",C22)),"Przychody","Koszty") -> Koszty | B22: B. Koszty działalności operacyjnej | C22: =C21 -> III. Usługi obce | D22: 58500010 | E22: 58500010 Wynajecie parkingu | F22: Wynikowe | G22: 8194.97 | H22: 2573.17 | I22: 11589.29 | J22: 9158.13 | K22: 9058.49 | L22: 7898.77 | M22: 8730.43 | N22: 8932.14 | O22: 8810.97 | P22: 8314.82 | Q22: 9074.49 | R22: 8581.96
A23: =IF(ISNUMBER(SEARCH("przychody",C23)),"Przychody","Koszty") -> Koszty | B23: B. Koszty działalności operacyjnej | C23: =C22 -> III. Usługi obce | D23: 58502003 | E23: 58502003 Ubezpieczenie biura | F23: Wynikowe | G23: 1876.68 | H23: 1894.43 | I23: 1894.43 | J23: 2340.5 | K23: 2102.49 | L23: 2102.49 | M23: 2102.49 | N23: 2102.49 | O23: 2102.49 | P23: 2102.49 | Q23: 2102.49 | R23: 2102.49
A24: =IF(ISNUMBER(SEARCH("przychody",C24)),"Przychody","Koszty") -> Koszty | B24: B. Koszty działalności operacyjnej | C24: =C23 -> III. Usługi obce | D24: 58504000 | E24: 58504000 Naprawa biura | F24: Wynikowe | G24: 2588.68 | H24: 1438.68 | I24: 1438.68 | J24: 1984.98 | K24: 2770.21 | L24: 3070.21 | M24: 1570.21 | N24: 1570.21 | O24: 1570.21 | P24: 1570.21 | Q24: 1570.21 | R24: 1570.21
A25: =IF(ISNUMBER(SEARCH("przychody",C25)),"Przychody","Koszty") -> Koszty | B25: B. Koszty działalności operacyjnej | C25: =C24 -> III. Usługi obce | D25: 58504001 | E25: 58504001 Eksploatacja biura | F25: Wynikowe | G25: 14370.53 | H25: 3620.96 | I25: 18678.36 | J25: 11848.6 | K25: 20305.13 | L25: 10875.58 | M25: 14371.05 | N25: 10492.94 | O25: 13155.2 | P25: 14632.73 | Q25: 12723.92 | R25: 12812.35
A26: =IF(ISNUMBER(SEARCH("przychody",C26)),"Przychody","Koszty") -> Koszty | B26: B. Koszty działalności operacyjnej | C26: =C25 -> III. Usługi obce | D26: 58504002 | E26: 58504002 Sprzątanie biura | F26: Wynikowe | G26: 8520.75 | H26: 1218.86 | I26: 8818.86 | J26: 8292.7 | K26: 6702.42 | L26: 8542.42 | M26: 9100.53 | N26: 8504.31 | O26: 9100.53 | P26: 8504.31 | Q26: 8802.42 | R26: 16700.53
A27: =IF(ISNUMBER(SEARCH("przychody",C27)),"Przychody","Koszty") -> Koszty | B27: B. Koszty działalności operacyjnej | C27: IV. Podatki i opłaty | D27: 58506000 | E27: 58506000 Opłaty prawne | F27: Wynikowe | G27: 0 | H27: 33385 | I27: 1 | J27: 0 | K27: 0 | L27: 3 | M27: 350 | N27: 1 | O27: 192 | P27: 900 | Q27: -900 | R27: 0
A28: =IF(ISNUMBER(SEARCH("przychody",C28)),"Przychody","Koszty") -> Koszty | B28: B. Koszty działalności operacyjnej | C28: III. Usługi obce | D28: 58506001 | E28: 58506001 Usługi prawnicze | F28: Wynikowe | G28: 28945.74 | H28: 4580 | I28: 9520 | J28: 4100 | K28: 3500 | L28: 3500 | M28: 3980 | N28: 3500 | O28: 3500 | P28: 3500 | Q28: 4160 | R28: 3740
A29: =IF(ISNUMBER(SEARCH("przychody",C29)),"Przychody","Koszty") -> Koszty | B29: B. Koszty działalności operacyjnej | C29: =C28 -> III. Usługi obce | D29: 58506003 | E29: 58506003 Usługi audytorskie | F29: Wynikowe | G29: 0 | H29: 12267.4 | I29: 12302.38 | J29: 0 | K29: 0 | L29: 0 | M29: 0 | N29: 0 | O29: 5020 | P29: 0 | Q29: 0 | R29: 24800
A30: =IF(ISNUMBER(SEARCH("przychody",C30)),"Przychody","Koszty") -> Koszty | B30: B. Koszty działalności operacyjnej | C30: =C29 -> III. Usługi obce | D30: 58506004 | E30: 58506004 Usługi doradztwa podatkowego | F30: Wynikowe | G30: 0 | H30: 0 | I30: 0 | J30: 41544.95 | K30: 0 | L30: 0 | M30: 80044.84 | N30: 0 | O30: 24470.6 | P30: 0 | Q30: 22658.13 | R30: 15496.6
A31: =IF(ISNUMBER(SEARCH("przychody",C31)),"Przychody","Koszty") -> Koszty | B31: B. Koszty działalności operacyjnej | C31: =C30 -> III. Usługi obce | D31: 58506006 | E31: 58506006 Usługi rekrutacyjne | F31: Wynikowe | G31: 6232.2 | H31: 0 | I31: 0 | J31: 0 | K31: 0 | L31: 0 | M31: 0 | N31: 499 | O31: 0 | P31: 0 | Q31: 0 | R31: 0
A32: =IF(ISNUMBER(SEARCH("przychody",C32)),"Przychody","Koszty") -> Koszty | B32: B. Koszty działalności operacyjnej | C32: =C31 -> III. Usługi obce | D32: 58507000 | E32: 58507000 Pozostałe usługi | F32: Wynikowe | G32: 2011 | H32: 1985.88 | I32: 1529.17 | J32: 1038.8 | K32: 6022.8 | L32: 4702.4 | M32: 25.95 | N32: 866.4 | O32: 3533.8 | P32: 1863.85 | Q32: 312.46 | R32: 2305.9
A33: =IF(ISNUMBER(SEARCH("przychody",C33)),"Przychody","Koszty") -> Koszty | B33: B. Koszty działalności operacyjnej | C33: =C32 -> III. Usługi obce | D33: 58507001 | E33: 58507001 Archiwizacja | F33: Wynikowe | G33: 0 | H33: 0 | I33: 1755 | J33: 0 | K33: 0 | L33: 0 | M33: 0 | N33: 0 | O33: 0 | P33: 147 | Q33: 0 | R33: 0
A34: =IF(ISNUMBER(SEARCH("przychody",C34)),"Przychody","Koszty") -> Koszty | B34: B. Koszty działalności operacyjnej | C34: =C33 -> III. Usługi obce | D34: 58521000 | E34: 58521000 Telefony stacjonarne | F34: Wynikowe | G34: 5551.22 | H34: 4237.84 | I34: 4189.37 | J34: 4301.69 | K34: 4306.5 | L34: 4199.25 | M34: 4188.08 | N34: 4320.84 | O34: 4167.29 | P34: 4213.27 | Q34: 4302.22 | R34: 4548.96
A35: =IF(ISNUMBER(SEARCH("przychody",C35)),"Przychody","Koszty") -> Koszty | B35: B. Koszty działalności operacyjnej | C35: =C34 -> III. Usługi obce | D35: 58522000 | E35: 58522000 Telefony komórkowe | F35: Wynikowe | G35: 1882.58 | H35: 3244.02 | I35: 1787.78 | J35: 1568.18 | K35: 1232.58 | L35: 1224.02 | M35: 360.22 | N35: 2063.55 | O35: 1459.83 | P35: 1478.4 | Q35: 1142.82 | R35: 1147.79
A36: =IF(ISNUMBER(SEARCH("przychody",C36)),"Przychody","Koszty") -> Koszty | B36: B. Koszty działalności operacyjnej | C36: =C35 -> III. Usługi obce | D36: 58525000 | E36: 58525000 Internet | F36: Wynikowe | G36: 1950 | H36: 0 | I36: 4519.99 | J36: 2329.99 | K36: 2329.99 | L36: 2190 | M36: 2190 | N36: 2190 | O36: 2190 | P36: 2190 | Q36: 2190 | R36: 2430
A37: =IF(ISNUMBER(SEARCH("przychody",C37)),"Przychody","Koszty") -> Koszty | B37: B. Koszty działalności operacyjnej | C37: =C36 -> III. Usługi obce | D37: 58527000 | E37: 58527000 Usługi pocztowe i kurierskie | F37: Wynikowe | G37: 1483.23 | H37: 2603.43 | I37: -1191.97 | J37: 1153.83 | K37: 1127.33 | L37: 1485.05 | M37: 2146.4 | N37: 1513.85 | O37: 1259.56 | P37: 1010.22 | Q37: 1281.68 | R37: 5077.31
A38: =IF(ISNUMBER(SEARCH("przychody",C38)),"Przychody","Koszty") -> Koszty | B38: B. Koszty działalności operacyjnej | C38: =C37 -> III. Usługi obce | D38: 58530200 | E38: 58530200 Koszty oprogramowania | F38: Wynikowe | G38: 11019.62 | H38: 8006.1 | I38: 7596.1 | J38: 13813.1 | K38: 7546.1 | L38: 7776.1 | M38: 7643.1 | N38: 6511.1 | O38: 6971.1 | P38: 10946.1 | Q38: 8639.1 | R38: 3006
A39: =IF(ISNUMBER(SEARCH("przychody",C39)),"Przychody","Koszty") -> Koszty | B39: B. Koszty działalności operacyjnej | C39: =C38 -> III. Usługi obce | D39: 58530500 | E39: 58530500 Usługi konsultingowe IT | F39: Wynikowe | G39: 3390 | H39: 4580 | I39: 4050 | J39: 5530 | K39: 4170 | L39: 3690 | M39: 4340 | N39: 2140 | O39: 4060 | P39: 5730 | Q39: 10320.2 | R39: 5600
A40: =IF(ISNUMBER(SEARCH("przychody",C40)),"Przychody","Koszty") -> Koszty | B40: B. Koszty działalności operacyjnej | C40: =C39 -> III. Usługi obce | D40: 58530700 | E40: 58530700 Pozostałe koszty IT | F40: Wynikowe | G40: 207.45 | H40: 0 | I40: 0 | J40: 1179.2 | K40: 14.7 | L40: 3210.27 | M40: 1121.43 | N40: 0 | O40: 0 | P40: 868.34 | Q40: 926.86 | R40: 0
...

Sheet 24 RziS Mapowanie
G1: =SUM(G3:G102) -> 3335057.1 | H1: =SUM(H3:H102) -> 3441549.9 | I1: =SUM(I3:I102) -> 3448161.1 | J1: =SUM(J3:J102) -> 926695.11 | K1: =SUM(K3:K102) -> 4829875.9 | L1: =SUM(L3:L102) -> 3832613.7 | M1: =SUM(M3:M102) -> 4066828.6 | N1: =SUM(N3:N102) -> 2154561 | ... P1: =SUM(P3:P102) -> 3790996.4 | Q1: =SUM(Q3:Q107) -> 3374417.5 | R1: =SUM(R3:R107) -> 7053888.5 | T1: -1
A2: Rodzaj1 | B2: Rodzaj2 | C2: Rodzaj3 | D2: Numer konta | E2: Nazwa konta | F2: Rodzaj konta (bilansowe/wynikowe) | G2: 2024-01 | H2: 2024-02 | I2: 2024-03 | J2: 2024-04 | K2: 2024-05 | L2: 2024-06 | M2: 2024-07 | N2: 2024-08 | O2: 2024-09 | P2: 2024-10 | Q2: 2024-11 | R2: 2024-12 | S2: 2024
A3: =IF(ISNUMBER(SEARCH("przychody",B3)),"Przychody","Koszty") -> Przychody | B3: A. Przychody netto ze sprzedaży i zrównane z nimi, w tym: | C3: =_xlfn.XLOOKUP(E3,'25 RZiS Zmapowane P+'!$E$2:$E$111,'25 RZiS Zmapowane P+'!$C$2:$C$111,0) -> I. Przychody netto ze sprzedaży produktów | D3: 44000000 | E3: 44000000 Przychód operacyjny - opłata za konosament | F3: Wynikowe | G3: 0 | H3: 0 | I3: 0 | J3: 0 | K3: 0 | L3: 0 | M3: 0 | N3: 0 | O3: 0 | P3: 0 | Q3: -112.36 | R3: 0 | S3: =SUM(_24[[#This Row],[2024-01]:[2024-12]]) -> -112.36
A4: =IF(ISNUMBER(SEARCH("przychody",B4)),"Przychody","Koszty") -> Przychody | B4: A. Przychody netto ze sprzedaży i zrównane z nimi, w tym: | C4: =_xlfn.XLOOKUP(E4,'25 RZiS Zmapowane P+'!$E$2:$E$111,'25 RZiS Zmapowane P+'!$C$2:$C$111,0) -> I. Przychody netto ze sprzedaży produktów | D4: 44000005 | E4: 44000005 Przychód operacyjny - opłata dokumentacyjna EXP | F4: Wynikowe | G4: 0 | H4: 0 | I4: 0 | J4: 0 | K4: 0 | L4: 0 | M4: 0 | N4: 0 | O4: 0 | P4: 0 | Q4: -153.29 | R4: 0 | S4: =SUM(_24[[#This Row],[2024-01]:[2024-12]]) -> -153.29
A5: =IF(ISNUMBER(SEARCH("przychody",B5)),"Przychody","Koszty") -> Przychody | B5: A. Przychody netto ze sprzedaży i zrównane z nimi, w tym: | C5: =_xlfn.XLOOKUP(E5,'25 RZiS Zmapowane P+'!$E$2:$E$111,'25 RZiS Zmapowane P+'!$C$2:$C$111,0) -> I. Przychody netto ze sprzedaży produktów | D5: 45510000 | E5: 45510000 Prowizja Cost+ | F5: Wynikowe | G5: 1850899 | H5: 1937526 | I5: 1838554 | J5: 453584 | K5: 1520140 | L5: 1520140 | M5: 2331123 | N5: 1636000 | O5: 1636000 | P5: 1635000 | Q5: 1635000 | R5: 3364855 | S5: =SUM(_24[[#This Row],[2024-01]:[2024-12]]) -> 21358821
A6: =IF(ISNUMBER(SEARCH("przychody",B6)),"Przychody","Koszty") -> Przychody | B6: D. Pozostałe przychody operacyjne | C6: =_xlfn.XLOOKUP(E6,'25 RZiS Zmapowane P+'!$E$2:$E$111,'25 RZiS Zmapowane P+'!$C$2:$C$111,0) -> IV. Inne przychody operacyjne | D6: 46012000 | E6: 46012000 Przychód operacyjny - nadpłaty | F6: Wynikowe | G6: 0 | H6: -4 | I6: -0.49 | J6: 0 | K6: 0 | L6: 0 | M6: 0 | N6: 0 | O6: 0 | P6: -10.34 | Q6: 0 | R6: -20.51 | S6: =SUM(_24[[#This Row],[2024-01]:[2024-12]]) -> -35.34
A7: =IF(ISNUMBER(SEARCH("przychody",B7)),"Przychody","Koszty") -> Przychody | B7: D. Pozostałe przychody operacyjne | C7: =_xlfn.XLOOKUP(E7,'25 RZiS Zmapowane P+'!$E$2:$E$111,'25 RZiS Zmapowane P+'!$C$2:$C$111,0) -> IV. Inne przychody operacyjne | D7: 46050000 | E7: 46050000 Przychód operacyjny - pozostałe | F7: Wynikowe | G7: 6616.25 | H7: 3474.05 | I7: 274 | J7: 6412.1 | K7: 1093 | L7: 207524.53 | M7: 364 | N7: 9190.58 | O7: 3890.97 | P7: 3517.94 | Q7: 3606.16 | R7: 3656.6 | S7: =SUM(_24[[#This Row],[2024-01]:[2024-12]]) -> 249620.18
A8: =IF(ISNUMBER(SEARCH("przychody",B8)),"Przychody","Koszty") -> Koszty | B8: B. Koszty działalności operacyjnej | C8: =_xlfn.XLOOKUP(E8,'25 RZiS Zmapowane P+'!$E$2:$E$111,'25 RZiS Zmapowane P+'!$C$2:$C$111,0) -> III. Usługi obce | D8: 53080000 | E8: 53080000 Koszt operacyjny - pozostałe koszty na termin mors | F8: Wynikowe | G8: 0 | H8: 0 | I8: 0 | J8: 0 | K8: 55401 | L8: 0 | M8: 0 | N8: 0 | O8: 0 | P8: 0 | Q8: 0 | R8: 0 | S8: =SUM(_24[[#This Row],[2024-01]:[2024-12]]) -> 55401
A9: =IF(ISNUMBER(SEARCH("przychody",B9)),"Przychody","Koszty") -> Koszty | B9: B. Koszty działalności operacyjnej | C9: =_xlfn.XLOOKUP(E9,'25 RZiS Zmapowane P+'!$E$2:$E$111,'25 RZiS Zmapowane P+'!$C$2:$C$111,0) -> III. Usługi obce | D9: 58500000 | E9: 58500000 Wynajęcie biura | F9: Wynikowe | G9: 21406.78 | H9: 5626.48 | I9: 21751.66 | J9: 21750.82 | K9: 3801.69 | L9: 4420.13 | M9: 28762.07 | N9: 7652.26 | O9: 7683.67 | P9: 7680.03 | Q9: 26297.01 | R9: 26647.1 | S9: =SUM(_24[[#This Row],[2024-01]:[2024-12]]) -> 183479.7
A10: =IF(ISNUMBER(SEARCH("przychody",B10)),"Przychody","Koszty") -> Koszty | B10: B. Koszty działalności operacyjnej | C10: =_xlfn.XLOOKUP(E10,'25 RZiS Zmapowane P+'!$E$2:$E$111,'25 RZiS Zmapowane P+'!$C$2:$C$111,0) -> III. Usługi obce | D10: 58500010 | E10: 58500010 Wynajecie parkingu | F10: Wynikowe | G10: 8307.36 | H10: 4965.21 | I10: 8420.35 | J10: 8757.84 | K10: 3524.39 | L10: 7557.76 | M10: 15464.41 | N10: 8034.57 | O10: 8125.68 | P10: 9291.91 | Q10: 8402.33 | R10: 10303.66 | S10: =SUM(_24[[#This Row],[2024-01]:[2024-12]]) -> 101155.47
A11: =IF(ISNUMBER(SEARCH("przychody",B11)),"Przychody","Koszty") -> Koszty | B11: B. Koszty działalności operacyjnej | C11: =_xlfn.XLOOKUP(E11,'25 RZiS Zmapowane P+'!$E$2:$E$111,'25 RZiS Zmapowane P+'!$C$2:$C$111,0) -> II. Zużycie materiałów i energii | D11: 58502000 | E11: 58502000 Energia cieplna | F11: Wynikowe | G11: 4208.23 | H11: 4306.92 | I11: 4073.16 | J11: 2428.72 | K11: 3835.33 | L11: 3948.43 | M11: 5932.9 | N11: 4848.09 | O11: 3860.73 | P11: 5514.71 | Q11: 3978.47 | R11: 4531.39 | S11: =SUM(_24[[#This Row],[2024-01]:[2024-12]]) -> 51467.08
A12: =IF(ISNUMBER(SEARCH("przychody",B12)),"Przychody","Koszty") -> Koszty | B12: B. Koszty działalności operacyjnej | C12: =_xlfn.XLOOKUP(E12,'25 RZiS Zmapowane P+'!$E$2:$E$111,'25 RZiS Zmapowane P+'!$C$2:$C$111,0) -> II. Zużycie materiałów i energii | D12: 58502001 | E12: 58502001 Woda | F12: Wynikowe | G12: 1388.54 | H12: 1792.07 | I12: 915.64 | J12: 1569.03 | K12: 1028.14 | L12: 1995.74 | M12: 1561.36 | N12: 695.43 | O12: 1698.22 | P12: 2170.34 | Q12: 1855.96 | R12: 2455.9 | S12: =SUM(_24[[#This Row],[2024-01]:[2024-12]]) -> 19126.37
A13: =IF(ISNUMBER(SEARCH("przychody",B13)),"Przychody","Koszty") -> Koszty | B13: B. Koszty działalności operacyjnej | C13: =_xlfn.XLOOKUP(E13,'25 RZiS Zmapowane P+'!$E$2:$E$111,'25 RZiS Zmapowane P+'!$C$2:$C$111,0) -> II. Zużycie materiałów i energii | D13: 58502002 | E13: 58502002 Energia elektryczna | F13: Wynikowe | G13: 1390.06 | H13: 7690.81 | I13: 4594.53 | J13: 3320.83 | K13: 3873.31 | L13: 3981.54 | M13: 5362.43 | N13: 1794.21 | O13: 7569.72 | P13: 5345.24 | Q13: 4732.72 | R13: 8656.65 | S13: =SUM(_24[[#This Row],[2024-01]:[2024-12]]) -> 58312.05
A14: =IF(ISNUMBER(SEARCH("przychody",B14)),"Przychody","Koszty") -> Koszty | B14: B. Koszty działalności operacyjnej | C14: =_xlfn.XLOOKUP(E14,'25 RZiS Zmapowane P+'!$E$2:$E$111,'25 RZiS Zmapowane P+'!$C$2:$C$111,0) -> III. Usługi obce | D14: 58502003 | E14: 58502003 Ubezpieczenie biura | F14: Wynikowe | G14: 1794.99 | H14: 1796.99 | I14: 1796.99 | J14: 2185.03 | K14: 1876.68 | L14: 1876.68 | M14: 1876.68 | N14: 1876.68 | O14: 1876.68 | P14: 1876.68 | Q14: 1876.68 | R14: 1876.68 | S14: =SUM(_24[[#This Row],[2024-01]:[2024-12]]) -> 22587.44
... A101: =IF(ISNUMBER(SEARCH("przychody",B101)),"Przychody","Koszty") -> Koszty | B101: H. Koszty finansowe | C101: =_xlfn.XLOOKUP(E101,'25 RZiS Zmapowane P+'!$E$2:$E$111,'25 RZiS Zmapowane P+'!$C$2:$C$111,0) -> IV. Inne | D101: 65528110 | E101: 65528110 Zrealiz ujemne różnice kursowe od należ | F101: Wynikowe | G101: 0 | H101: 0 | I101: 0 | J101: 0 | K101: 0 | L101: 0 | M101: 0 | N101: 0 | O101: 0 | P101: 0 | Q101: 0 | R101: 0 | S101: =SUM(_24[[#This Row],[2024-01]:[2024-12]]) -> 0
A102: =IF(ISNUMBER(SEARCH("przychody",B102)),"Przychody","Koszty") -> Koszty | B102: J. Podatek dochodowy | D102: 70000000 | E102: 70000000 Podatek dochodowy - bieżacy okres | F102: Wynikowe | G102: 0 | H102: 83990 | I102: 83990 | J102: 83990 | K102: 413010.75 | L102: 83990 | M102: 83990 | N102: 83990 | O102: 83990 | P102: 374175.12 | Q102: 83990 | R102: -1081873.3 | S102: =SUM(_24[[#This Row],[2024-01]:[2024-12]]) -> 377232.61
A103: =IF(ISNUMBER(SEARCH("przychody",B103)),"Przychody","Koszty") -> Przychody | B103: A. Przychody netto ze sprzedaży i zrównane z nimi, w tym: | C103: =_xlfn.XLOOKUP(E103,'25 RZiS Zmapowane P+'!$E$2:$E$111,'25 RZiS Zmapowane P+'!$C$2:$C$111,0) -> I. Przychody netto ze sprzedaży produktów | D103: 44006000 | E103: 44006000 Przychód operacyjny - korekta manifestu | F103: Wynikowe | Q103: -340.23 | R103: 0 | S103: =SUM(_24[[#This Row],[2024-01]:[2024-12]]) -> -340.23
B104: C. Zysk/ (strata) ze sprzedaży | G104: =SUMIF($B$3:$B$107,"A. Przychody netto ze sprzedaży i zrównane z nimi, w tym:",G3:G107) - SUMIF($B$3:$B$107,"B. Koszty działalności operacyjnej",G3:G107) -> 376375.95 | H104: =SUMIF($B$3:$B$107,"A. Przychody netto ze sprzedaży i zrównane z nimi, w tym:",H3:H107) - SUMIF($B$3:$B$107,"B. Koszty działalności operacyjnej",H3:H107) -> 520778.51 | I104: =SUMIF($B$3:$B$107,"A. Przychody netto ze sprzedaży i zrównane z nimi, w tym:",I3:I107) - SUMIF($B$3:$B$107,"B. Koszty działalności operacyjnej",I3:I107) -> 314197.75 | J104: =SUMIF($B$3:$B$107,"A. Przychody netto ze sprzedaży i zrównane z nimi, w tym:",J3:J107) - SUMIF($B$3:$B$107,"B. Koszty działalności operacyjnej",J3:J107) -> 71175.8 | K104: =SUMIF($B$3:$B$107,"A. Przychody netto ze sprzedaży i zrównane z nimi, w tym:",K3:K107) - SUMIF($B$3:$B$107,"B. Koszty działalności operacyjnej",K3:K107) -> -1376572.4 | L104: =SUMIF($B$3:$B$107,"A. Przychody netto ze sprzedaży i zrównane z nimi, w tym:",L3:L107) - SUMIF($B$3:$B$107,"B. Koszty działalności operacyjnej",L3:L107) -> -499558.88 | M104: =SUMIF($B$3:$B$107,"A. Przychody netto ze sprzedaży i zrównane z nimi, w tym:",M3:M107) - SUMIF($B$3:$B$107,"B. Koszty działalności operacyjnej",M3:M107) -> 740299.73 | N104: =SUMIF($B$3:$B$107,"A. Przychody netto ze sprzedaży i zrównane z nimi, w tym:",N3:N107) - SUMIF($B$3:$B$107,"B. Koszty działalności operacyjnej",N3:N107) -> 1210295.5 | ... R104: =SUMIF($B$3:$B$107,"A. Przychody netto ze sprzedaży i zrównane z nimi, w tym:",R3:R107) - SUMIF($B$3:$B$107,"B. Koszty działalności operacyjnej",R3:R107) -> 88619.84 | S104: =SUM(_24[[#This Row],[2024-01]:[2024-12]]) -> 250976.11
B105: F. Zysk/ (strata) z działalności operacyjnej | G105: =G104 + SUMIF($B$3:$B$107,"D. Pozostałe przychody operacyjne",G3:G107) - SUMIF($B$3:$B$107,"E. Pozostałe koszty operacyjne",G3:G107) -> 379992.2 | H105: =H104 + SUMIF($B$3:$B$107,"D. Pozostałe przychody operacyjne",H3:H107) - SUMIF($B$3:$B$107,"E. Pozostałe koszty operacyjne",H3:H107) -> 524248.56 | I105: =I104 + SUMIF($B$3:$B$107,"D. Pozostałe przychody operacyjne",I3:I107) - SUMIF($B$3:$B$107,"E. Pozostałe koszty operacyjne",I3:I107) -> 314475.32 | J105: =J104 + SUMIF($B$3:$B$107,"D. Pozostałe przychody operacyjne",J3:J107) - SUMIF($B$3:$B$107,"E. Pozostałe koszty operacyjne",J3:J107) -> 77587.9 | K105: =K104 + SUMIF($B$3:$B$107,"D. Pozostałe przychody operacyjne",K3:K107) - SUMIF($B$3:$B$107,"E. Pozostałe koszty operacyjne",K3:K107) -> -1380468.1 | L105: =L104 + SUMIF($B$3:$B$107,"D. Pozostałe przychody operacyjne",L3:L107) - SUMIF($B$3:$B$107,"E. Pozostałe koszty operacyjne",L3:L107) -> -290792.9 | M105: =M104 + SUMIF($B$3:$B$107,"D. Pozostałe przychody operacyjne",M3:M107) - SUMIF($B$3:$B$107,"E. Pozostałe koszty operacyjne",M3:M107) -> 787323.86 | N105: =N104 + SUMIF($B$3:$B$107,"D. Pozostałe przychody operacyjne",N3:N107) - SUMIF($B$3:$B$107,"E. Pozostałe koszty operacyjne",N3:N107) -> 1219868.3 | ... R105: =R104 + SUMIF($B$3:$B$107,"D. Pozostałe przychody operacyjne",R3:R107) - SUMIF($B$3:$B$107,"E. Pozostałe koszty operacyjne",R3:R107) -> 100759.51 | S105: =SUM(_24[[#This Row],[2024-01]:[2024-12]]) -> 714003.81
B106: I. Zysk/ (strata) brutto | G106: =G105 + SUMIF($B$3:$B$107,"G. Przychody finansowe",G3:G107) - SUMIF($B$3:$B$107,"H. Koszty finansowe",G3:G107) -> 379978.41 | H106: =H105 + SUMIF($B$3:$B$107,"G. Przychody finansowe",H3:H107) - SUMIF($B$3:$B$107,"H. Koszty finansowe",H3:H107) -> 524432.24 | I106: =I105 + SUMIF($B$3:$B$107,"G. Przychody finansowe",I3:I107) - SUMIF($B$3:$B$107,"H. Koszty finansowe",I3:I107) -> 313492.04 | J106: =J105 + SUMIF($B$3:$B$107,"G. Przychody finansowe",J3:J107) - SUMIF($B$3:$B$107,"H. Koszty finansowe",J3:J107) -> 77414.99 | K106: =K105 + SUMIF($B$3:$B$107,"G. Przychody finansowe",K3:K107) - SUMIF($B$3:$B$107,"H. Koszty finansowe",K3:K107) -> -1374106.3 | L106: =L105 + SUMIF($B$3:$B$107,"G. Przychody finansowe",L3:L107) - SUMIF($B$3:$B$107,"H. Koszty finansowe",L3:L107) -> -290811.78 | M106: =M105 + SUMIF($B$3:$B$107,"G. Przychody finansowe",M3:M107) - SUMIF($B$3:$B$107,"H. Koszty finansowe",M3:M107) -> 784525.63 | N106: =N105 + SUMIF($B$3:$B$107,"G. Przychody finansowe",N3:N107) - SUMIF($B$3:$B$107,"H. Koszty finansowe",N3:N107) -> 1220574.7 | ... R106: =R105 + SUMIF($B$3:$B$107,"G. Przychody finansowe",R3:R107) - SUMIF($B$3:$B$107,"H. Koszty finansowe",R3:R107) -> 104937.31 | S106: =SUM(_24[[#This Row],[2024-01]:[2024-12]]) -> 719521.55
B107: L. Zysk/ (strata) netto | G107: =G113 -> 379978.41 | H107: =H113 -> 440442.24 | I107: =I113 -> 229502.04 | J107: =J113 -> -6575.01 | K107: =K113 -> -1787117.1 | L107: =L113 -> -374801.78 | M107: =M113 -> 700535.63 | N107: =N113 -> 1136584.7 | ... R107: =R113 -> 1186810.6 | S107: =SUM(_24[[#This Row],[2024-01]:[2024-12]]) -> 342288.94
F111: P | G111: =SUMIF($A$3:$A$103,"Przychody",G3:G103) -> 1857517.7 | H111: =SUMIF($A$3:$A$103,"Przychody",H3:H103) -> 1940996.1 | I111: =SUMIF($A$3:$A$103,"Przychody",I3:I103) -> 1838831.6 | J111: =SUMIF($A$3:$A$103,"Przychody",J3:J103) -> 460060.05 | K111: =SUMIF($A$3:$A$103,"Przychody",K3:K103) -> 1521379.4 | L111: =SUMIF($A$3:$A$103,"Przychody",L3:L103) -> 1728906 | M111: =SUMIF($A$3:$A$103,"Przychody",M3:M103) -> 2383682.1 | N111: =SUMIF($A$3:$A$103,"Przychody",N3:N103) -> 1645572.9 | ... R111: =SUMIF($A$3:$A$103,"Przychody",R3:R103) -> 3379785.9
F112: K | G112: =SUMIF($A$3:$A$103,"Koszty",G3:G103) -> 1477539.3 | H112: =SUMIF($A$3:$A$103,"Koszty",H3:H103) -> 1500553.8 | I112: =SUMIF($A$3:$A$103,"Koszty",I3:I103) -> 1609329.5 | J112: =SUMIF($A$3:$A$103,"Koszty",J3:J103) -> 466635.06 | K112: =SUMIF($A$3:$A$103,"Koszty",K3:K103) -> 3308496.5 | L112: =SUMIF($A$3:$A$103,"Koszty",L3:L103) -> 2103707.8 | M112: =SUMIF($A$3:$A$103,"Koszty",M3:M103) -> 1683146.5 | N112: =SUMIF($A$3:$A$103,"Koszty",N3:N103) -> 508988.15 | ... R112: =SUMIF($A$3:$A$103,"Koszty",R3:R103) -> 2192975.4
F113: Z | G113: =G111-G112 -> 379978.41 | H113: =H111-H112 -> 440442.24 | I113: =I111-I112 -> 229502.04 | J113: =J111-J112 -> -6575.01 | K113: =K111-K112 -> -1787117.1 | L113: =L111-L112 -> -374801.78 | M113: =M111-M112 -> 700535.63 | N113: =N111-N112 -> 1136584.7 | ... R113: =R111-R112 -> 1186810.6 | S113: =SUM(G113:R113) -> 342288.94
G115: 2024-01 | H115: 2024-02 | I115: 2024-03 | J115: 2024-04 | K115: 2024-05 | L115: 2024-06 | M115: 2024-07 | N115: 2024-08 | O115: 2024-09 | P115: 2024-10 | Q115: 2024-11 | R115: 2024-12

Sheet Bilans ->>>
A1: B

Sheet Check Bilansu 25
A2: Etykiety wierszy | B2: Suma z BZ | E2: Etykiety wierszy | F2: Suma z BZ
A3: A. Aktywa trwałe | B3: 7537505.9 | E3: A. Aktywa trwałe | F3: 7537505.9
A4: I. Wartości niematerialne i prawne | B4: 7412 | E4: I. Wartości niematerialne i prawne | F4: 7412
A5: II. Rzeczowe aktywa trwałe | B5: 6727838.4 | E5: II. Rzeczowe aktywa trwałe | F5: 6727838.4
A6: V. Długoterminowe rozliczenia międzyokresowe | B6: 802255.52 | E6: V. Długoterminowe rozliczenia międzyokresowe | F6: 802255.52
A7: B. Aktywa obrotowe | B7: 95670395 | E7: B. Aktywa obrotowe | F7: 95670395
A8: II. Należności krótkoterminowe | B8: 95542030 | E8: II. Należności krótkoterminowe | F8: 95542030
A9: III. Inwestycje krótkoterminowe | B9: 102893.47 | E9: III. Inwestycje krótkoterminowe | F9: 102893.47
A10: IV. Krótkoterminowe rozliczenia międzyokresowe | B10: 25470.62 | E10: IV. Krótkoterminowe rozliczenia międzyokresowe | F10: 25470.62
A11: A. Kapitał (fundusz) własny | B11: 2604310.9 | E11: A. Kapitał (fundusz) własny | F11: -2604310.9
A12: I. Kapitał (fundusz) podstawowy | B12: 50000 | E12: I. Kapitał (fundusz) podstawowy | F12: -50000
B13: 50000 | E13: V. Zysk/ (strata) z lat ubiegłych | F13: -2229674.6
A14: (puste) | B14: 50000 | E14: VI. Zysk/ (strata) netto | F14: -324636.34
A15: (puste) | B15: 50000 | E15: B. Zobowiązania i rezerwy na zobowiązania | F15: -1.0060359e+08
A16: V. Zysk/ (strata) z lat ubiegłych | B16: 2229674.6 | E16: I. Rezerwy na zobowiązania | F16: -3005996.9
A17: VI. Zysk/ (strata) netto | B17: 324636.34 | E17: III. Zobowiązania krótkoterminowe | F17: -97597593
A18: B. Zobowiązania i rezerwy na zobowiązania | B18: 1.0060359e+08 | E18: Suma końcowa | F18: 0
A19: I. Rezerwy na zobowiązania | B19: 3005996.9
A20: 1. Rezerwa z tytułu odroczonego podatku dochodowego | B20: 79.17
A21: b) krótkoterminowe | B21: 79.17
A22: (puste) | B22: 79.17
A23: 2. Rezerwa na świadczenia emerytalne i podobne | B23: 498323
A24: a) długoterminowe | B24: 498323
A25: (puste) | B25: 498323
A26: 3. Pozostałe rezerwy | B26: 2507594.7
A27: a) długoterminowe | B27: 1055133.9
A28: (puste) | B28: 1055133.9
A29: b) krótkoterminowe | B29: 1452460.8
A30: (puste) | B30: 1452460.8 | D30: =B7-(B31+B30) -> -3379658.9 | E30: =B7/(B30+B31) -> 0.96587928
A31: III. Zobowiązania krótkoterminowe | B31: 97597593 | E31: =B7/B31 -> 0.98025363
A32: 3. Należności od pozostałych jednostek | B32: 0 | E32: =B7/(B31+B7) -> 0.49501418
A33: (puste) | B33: 0
A34: (puste) | B34: 0
A35: 3. Zobowiązania wobec pozostałych jednostek | B35: 0
A36: h) z tytułu wynagrodzeń | B36: 0
A37: (puste) | B37: 0
A38: 3. Zobowiązania wobec pozostałych jednostek | B38: 97597593
A39: d) z tytułu dostaw i usług, o okresie wymagalności: | B39: 106600.2
A40: - do 12 miesięcy | B40: 106600.2
A41: g) z tytułu podatków, ceł, ubezpieczeń społecznych i zdrowotnych oraz innych tytułów publicznoprawnych | B41: 1131853.4
...

Sheet 25 Mapowanie Bilans P+
A1: Rodzaj1 | B1: Rodzaj2 | C1: Rodzaj3 | D1: Rodzaj4 | E1: Rodzaj5 | F1: Rodzaj6 | G1: Numer konta | H1: Nazwa konta | I1: Rodzaj konta (bilansowe/wynikowe) | J1: 2025-01 | K1: 2025-02 | L1: 2025-03 | M1: 2025-04 | N1: 2025-05 | O1: 2025-06 | P1: 2025-07 | Q1: 2025-08 | R1: 2025-09 | S1: 2025-10 | T1: 2025-11 | U1: 2025-12 | V1: BZ | W1: BZ 2025 | X1: Check:
A2: =IF(ISNUMBER(SEARCH("aktywa",B2)),"Aktywa","Pasywa") -> Aktywa | B2: A. Aktywa trwałe | C2: I. Wartości niematerialne i prawne | D2: 3. Inne wartości niematerialne i prawne | G2: 11000100 | H2: 11000100 Oprogramowanie i licencje IT - Wartość nabycia | I2: Bilansowe | J2: 77463.01 | K2: 0 | L2: 0 | M2: 0 | N2: 0 | O2: 0 | P2: 0 | Q2: 0 | R2: 0 | S2: 0 | T2: 0 | U2: 0 | V2: 77463.01 | W2: 77463.01 | X2: 0 | Z2: Aktywa/Pasywa
A3: =IF(ISNUMBER(SEARCH("aktywa",B3)),"Aktywa","Pasywa") -> Aktywa | B3: A. Aktywa trwałe | C3: I. Wartości niematerialne i prawne | D3: 3. Inne wartości niematerialne i prawne | G3: 11000400 | H3: 11000400 Oprogramowanie i licencje IT - Umorzenie | I3: Bilansowe | J3: -59859.51 | K3: -926.5 | L3: -926.5 | M3: -926.5 | N3: -926.5 | O3: -926.5 | P3: -926.5 | Q3: -926.5 | R3: -926.5 | S3: -926.5 | T3: -926.5 | U3: -926.5 | V3: -70051.01 | W3: -70051.01 | X3: 0 | Z3: A
A4: =IF(ISNUMBER(SEARCH("aktywa",B4)),"Aktywa","Pasywa") -> Aktywa | B4: A. Aktywa trwałe | C4: II. Rzeczowe aktywa trwałe | D4: 1. Środki trwałe | E4: b) budynki, lokale, prawa do lokali i obiekty inżynierii lądowej i wodnej | G4: 11502100 | H4: 11502100 Budynki - Wartość nabycia | I4: Bilansowe | J4: 8316577 | K4: 0 | L4: 0 | M4: 0 | N4: 0 | O4: 0 | P4: 0 | Q4: 0 | R4: 0 | S4: 0 | T4: 0 | U4: 0 | V4: 8316577 | W4: 8316577 | X4: 0 | Z4: I
A5: =IF(ISNUMBER(SEARCH("aktywa",B5)),"Aktywa","Pasywa") -> Aktywa | B5: A. Aktywa trwałe | C5: II. Rzeczowe aktywa trwałe | D5: 1. Środki trwałe | E5: b) budynki, lokale, prawa do lokali i obiekty inżynierii lądowej i wodnej | G5: 11502400 | H5: 11502400 Budynki - Umorzenie | I5: Bilansowe | J5: -1679956.6 | K5: -17326.2 | L5: -17326.21 | M5: -17326.2 | N5: -17326.2 | O5: -17326.2 | P5: -17326.2 | Q5: -17326.2 | R5: -17326.21 | S5: -17326.2 | T5: -17326.2 | U5: -17326.2 | V5: -1870544.8 | W5: -1870544.8 | X5: 0 | Z5: 1.
A6: =IF(ISNUMBER(SEARCH("aktywa",B6)),"Aktywa","Pasywa") -> Aktywa | B6: A. Aktywa trwałe | C6: II. Rzeczowe aktywa trwałe | D6: 2. Środki trwałe w budowie | G6: 11504100 | H6: 11504100 Nakłady w obcych środkach trwał - Wartość nabycia | I6: Bilansowe | J6: 204102.98 | K6: 0 | L6: 0 | M6: 0 | N6: 0 | O6: 0 | P6: 0 | Q6: 0 | R6: 0 | S6: 0 | T6: 0 | U6: 0 | V6: 204102.98 | W6: 204102.98 | X6: 0 | Z6: a)
A7: =IF(ISNUMBER(SEARCH("aktywa",B7)),"Aktywa","Pasywa") -> Aktywa | B7: A. Aktywa trwałe | C7: II. Rzeczowe aktywa trwałe | D7: 2. Środki trwałe w budowie | G7: 11504400 | H7: 11504400 Nakłady w obcych środkach trwał - Umorzenie | I7: Bilansowe | J7: -43327.35 | K7: -313.45 | L7: -313.46 | M7: -313.46 | N7: -6769.34 | O7: -1604.64 | P7: -1604.64 | Q7: -1604.63 | R7: -1604.64 | S7: -1604.63 | T7: -1604.63 | U7: -1604.64 | V7: -62269.51 | W7: -62269.51 | X7: 0 | Z7: -
A8: =IF(ISNUMBER(SEARCH("aktywa",B8)),"Aktywa","Pasywa") -> Aktywa | B8: A. Aktywa trwałe | C8: II. Rzeczowe aktywa trwałe | D8: 1. Środki trwałe | E8: c) urządzenia techniczne i maszyny | G8: 11508100 | H8: 11508100 Komputery i sprzęt IT - Wartość nabycia | I8: Bilansowe | J8: 1021948.2 | K8: 6806.51 | L8: -2240.07 | M8: 22451.59 | N8: 459 | O8: 0 | P8: 13387.33 | Q8: -1499.06 | R8: 157.44 | S8: 9879.54 | T8: 2065.04 | U8: 6725.93 | V8: 1080141.5 | W8: 1080141.5 | X8: 0
A9: =IF(ISNUMBER(SEARCH("aktywa",B9)),"Aktywa","Pasywa") -> Aktywa | B9: A. Aktywa trwałe | C9: II. Rzeczowe aktywa trwałe | D9: 1. Środki trwałe | E9: c) urządzenia techniczne i maszyny | G9: 11508400 | H9: 11508400 Komputery i sprzęt IT - Umorzenie | I9: Bilansowe | J9: -1009268.7 | K9: -3437.15 | L9: -3035.42 | M9: -22451.59 | N9: -459 | O9: 0 | P9: -13387.33 | Q9: 920.06 | R9: 421.56 | S9: -9879.54 | T9: -2065.04 | U9: -6725.93 | V9: -1069368.1 | W9: -1069368.1 | X9: 0
A10: =IF(ISNUMBER(SEARCH("aktywa",B10)),"Aktywa","Pasywa") -> Aktywa | B10: A. Aktywa trwałe | C10: II. Rzeczowe aktywa trwałe | D10: 1. Środki trwałe | E10: e) inne środki trwałe | G10: 11514100 | H10: 11514100 Meble i wyposażenie - Wartość nabycia | I10: Bilansowe | J10: 1071105.1 | K10: 343.9 | L10: 0 | M10: 16465.4 | N10: 0 | O10: 0 | P10: 1998.72 | Q10: 0 | R10: 0 | S10: 2900 | T10: 0 | U10: 0 | V10: 1092813.1 | W10: 1092813.1 | X10: 0
A11: =IF(ISNUMBER(SEARCH("aktywa",B11)),"Aktywa","Pasywa") -> Aktywa | B11: A. Aktywa trwałe | C11: II. Rzeczowe aktywa trwałe | D11: 1. Środki trwałe | E11: e) inne środki trwałe | G11: 11514400 | H11: 11514400 Meble i wyposażenie - Umorzenie | I11: Bilansowe | J11: -985003.34 | K11: -579 | L11: -3421.14 | M11: -18409.02 | N11: -1749.81 | O11: -1749.8 | P11: -3748.51 | Q11: -1749.81 | R11: -1749.8 | S11: -4649.8 | T11: -1749.8 | U11: -816.98 | V11: -1025376.8 | W11: -1025376.8 | X11: 0
A12: =IF(ISNUMBER(SEARCH("aktywa",B12)),"Aktywa","Pasywa") -> Aktywa | B12: A. Aktywa trwałe | C12: II. Rzeczowe aktywa trwałe | D12: 1. Środki trwałe | E12: d) środki transportu | G12: 11518100 | H12: 11518100 Samochody - Wartość nabycia | I12: Bilansowe | J12: 1042482.4 | K12: 0 | L12: -152490.19 | M12: 0 | N12: 0 | O12: 0 | P12: 0 | Q12: 0 | R12: 0 | S12: 0 | T12: 0 | U12: 0 | V12: 889992.25 | W12: 889992.25 | X12: 0
A13: =IF(ISNUMBER(SEARCH("aktywa",B13)),"Aktywa","Pasywa") -> Aktywa | B13: A. Aktywa trwałe | C13: II. Rzeczowe aktywa trwałe | D13: 1. Środki trwałe | E13: d) środki transportu | G13: 11518400 | H13: 11518400 Samochody - Umorzenie | I13: Bilansowe | J13: -881165.3 | K13: -16101 | L13: 133847.71 | M13: -13559.44 | N13: -8113.52 | O13: -6162.77 | P13: -6162.45 | Q13: -6162.46 | R13: -6162.48 | S13: -6162.47 | T13: -6162.46 | U13: -6162.46 | V13: -828229.1 | W13: -828229.1 | X13: 0
A14: =IF(ISNUMBER(SEARCH("aktywa",B14)),"Aktywa","Pasywa") -> Aktywa | B14: A. Aktywa trwałe | C14: V. Długoterminowe rozliczenia międzyokresowe | D14: 2. Inne rozliczenia międzyokresowe | G14: 13500000 | H14: 13500000 Kaucje i depozyty | I14: Bilansowe | J14: 159228 | K14: 0 | L14: 0 | M14: 0 | N14: 0 | O14: 0 | P14: 0 | Q14: 0 | R14: 0 | S14: 0 | T14: 0 | U14: 0 | V14: 159228 | W14: 159228 | X14: 0
A15: =IF(ISNUMBER(SEARCH("aktywa",B15)),"Aktywa","Pasywa") -> Aktywa | B15: B. Aktywa obrotowe | C15: II. Należności krótkoterminowe | D15: 3. Należności od pozostałych jednostek | E15: a) z tytułu dostaw i usług, o okresie spłaty: | F15: - do 12 miesięcy | G15: 15500000 | H15: 15500000 Należności handlowe - podmioty niepowiązane | I15: Bilansowe | J15: 15147.43 | K15: 769.25 | L15: -2600 | M15: -2600 | N15: -2600 | O15: -2600 | P15: -516.68 | Q15: 173.75 | R15: 36.9 | S15: 19365.65 | T15: -5000 | U15: 26568.67 | V15: 46144.97 | W15: 46144.97 | X15: 0
A16: =IF(ISNUMBER(SEARCH("aktywa",B16)),"Aktywa","Pasywa") -> Aktywa | B16: B. Aktywa obrotowe | C16: II. Należności krótkoterminowe | D16: 3. Należności od pozostałych jednostek | E16: c) inne | G16: 15500800 | H16: 15500800 Odpisy na należności handlowe - podm niepowiązane | I16: Bilansowe | J16: 0 | K16: 0 | L16: 0 | M16: 0 | N16: 0 | O16: 0 | P16: 0 | Q16: 0 | R16: 0 | S16: 0 | T16: 0 | U16: 0 | V16: 0 | W16: 0 | X16: 0
A17: =IF(ISNUMBER(SEARCH("aktywa",B17)),"Aktywa","Pasywa") -> Aktywa | B17: B. Aktywa obrotowe | C17: II. Należności krótkoterminowe | D17: 3. Należności od pozostałych jednostek | E17: a) z tytułu dostaw i usług, o okresie spłaty: | F17: - do 12 miesięcy | G17: 15500999 | H17: 15500999 Należności handlowe podm niepow - wycena bilansowa | I17: Bilansowe | J17: 0 | K17: 0 | L17: 0 | M17: 0 | N17: 0 | O17: 0 | P17: 0 | Q17: 0 | R17: 0 | S17: 0 | T17: 0 | U17: 319.97 | V17: 319.97 | W17: 319.97 | X17: 0
