Workbook

Sheet Final_Data
A1: L.P | B1: Feeling close to loved ones | C1: Staying connected with the world | D1: I haven't thought about it much | E1: Peace and Calm to Brain soulfully | F1: Staying independent and alert | G1: Enjoying music, laughter, and life | H1: Hearing_FOMO | I1: Hearing_Test_Barrier_Modified | J1: Missed_Important_Sounds | K1: Left_Out_Due_To_Hearing | L1: Daily_Headphone_Use | M1: Belief_Early_Hearing_Care | N1: Last_Hearing_Test_Method | O1: Interest_in_Hearing_App | P1: Quick tests | Q1: Doctor consultation | R1: Game-based interaction | S1: Earphone calibration | T1: Soft guidance | U1: Regular testing reminders | V1: Detailed report generation | W1: Personalized volume adjustments | X1: Audio amplifier or sound booster | Y1: Report sharing options | Z1: Awareness_on_hearing_and_Willingness_to_invest | AA1: Paid_App_Test_Interest | AB1: Age_group | AC1: Ear_Discomfort_After_Use
A2: 1 | B2: 0 | C2: 1 | D2: 0 | E2: 0 | F2: 1 | G2: 1 | H2: Sometimes | I2: Cost | J2: Yes, in family conversations | K2: Yes, often | L2: NA | M2: 5 | N2: Self - application | O2: Yes, that would be helpful | P2: 0 | Q2: 0 | R2: 0 | S2: 0 | T2: 1 | U2: 0 | V2: 0 | W2: 0 | X2: 0 | Y2: 1 | Z2: Yes | AA2: Maybe, if it offers good value | AB2: 18 - 24 | AC2: No
A3: 2 | B3: 0 | C3: 1 | D3: 0 | E3: 0 | F3: 1 | G3: 0 | H3: Rarely | I3: No need | J3: Yes, in public spaces (trains, shops, announcements) | K3: Only in noisy places | L3: NA | M3: 5 | N3: Self - application | O3: Yes, that would be helpful | P3: 0 | Q3: 0 | R3: 0 | S3: 0 | T3: 0 | U3: 0 | V3: 0 | W3: 0 | X3: 0 | Y3: 0 | Z3: Yes | AA3: No, I prefer getting tested at a hospital | AB3: 18 - 24 | AC3: Yes
A4: 3 | B4: 0 | C4: 0 | D4: 1 | E4: 0 | F4: 1 | G4: 0 | H4: Rarely | I4: Shame | J4: Yes, during important work or school meetings | K4: Sometimes | L4: NA | M4: 5 | N4: Self - application | O4: Maybe, if it's easy to use | P4: 0 | Q4: 0 | R4: 0 | S4: 0 | T4: 1 | U4: 0 | V4: 0 | W4: 0 | X4: 0 | Y4: 0 | Z4: No | AA4: Yes, definitely | AB4: 18 - 24 | AC4: Maybe
A5: 4 | B5: 0 | C5: 0 | D5: 0 | E5: 0 | F5: 1 | G5: 0 | H5: Yes often | I5: Lack of awareness | J5: Yes, during important work or school meetings | K5: Sometimes | L5: 1-2 hours | M5: 4 | N5: I've never taken a hearing test | O5: Yes, that would be helpful | P5: 0 | Q5: 0 | R5: 1 | S5: 0 | T5: 0 | U5: 0 | V5: 0 | W5: 0 | X5: 0 | Y5: 0 | Z5: Yes | AA5: Yes, definitely | AB5: 18 - 24 | AC5: Occasionally
A6: 5 | B6: 0 | C6: 0 | D6: 0 | E6: 0 | F6: 1 | G6: 0 | H6: Never | I6: Lack of awareness | J6: No, I usually hear things well | K6: Only in noisy places | L6: Less than 1 hour | M6: 5 | N6: I've never taken a hearing test | O6: No, I don't think it's necessary | P6: 1 | Q6: 0 | R6: 1 | S6: 0 | T6: 0 | U6: 0 | V6: 1 | W6: 0 | X6: 0 | Y6: 0 | Z6: No | AA6: No, I prefer getting tested at a hospital | AB6: 25 - 34 | AC6: No
A7: 6 | B7: 0 | C7: 0 | D7: 0 | E7: 0 | F7: 0 | G7: 1 | H7: Rarely | I7: Lack of awareness | J7: Yes, in family conversations | K7: Never | L7: Less than 1 hour | M7: 5 | N7: I've never taken a hearing test | O7: No, I don't think it's necessary | P7: 1 | Q7: 0 | R7: 0 | S7: 0 | T7: 0 | U7: 0 | V7: 0 | W7: 0 | X7: 0 | Y7: 0 | Z7: Yes | AA7: No, I prefer getting tested at a hospital | AB7: 25 - 34 | AC7: No
A8: 7 | B8: 1 | C8: 0 | D8: 0 | E8: 0 | F8: 1 | G8: 0 | H8: Yes often | I8: Lack of awareness | J8: Yes, in family conversations | K8: Only in noisy places | L8: 2-4 hours | M8: 4 | N8: At a hospital or clinic | O8: Yes, that would be helpful | P8: 1 | Q8: 0 | R8: 1 | S8: 0 | T8: 0 | U8: 0 | V8: 0 | W8: 0 | X8: 0 | Y8: 0 | Z8: Yes | AA8: Maybe, if it offers good value | AB8: 18 - 24 | AC8: Yes
A9: 8 | B9: 1 | C9: 1 | D9: 0 | E9: 0 | F9: 1 | G9: 1 | H9: Rarely | I9: Cost | J9: No, I usually hear things well | K9: Never | L9: 2-4 hours | M9: 4 | N9: At a hospital or clinic | O9: Maybe, if it's easy to use | P9: 1 | Q9: 0 | R9: 1 | S9: 0 | T9: 0 | U9: 1 | V9: 0 | W9: 1 | X9: 0 | Y9: 0 | Z9: Yes | AA9: Yes, definitely | AB9: 18 - 24 | AC9: Yes
A10: 9 | B10: 0 | C10: 0 | D10: 0 | E10: 0 | F10: 0 | G10: 1 | H10: Sometimes | I10: Lack of awareness | J10: Yes, in public spaces (trains, shops, announcements) | K10: Only in noisy places | L10: Less than 1 hour | M10: 5 | N10: I've never taken a hearing test | O10: Yes, that would be helpful | P10: 1 | Q10: 1 | R10: 1 | S10: 0 | T10: 0 | U10: 1 | V10: 0 | W10: 0 | X10: 1 | Y10: 0 | Z10: Yes | AA10: Maybe, if it offers good value | AB10: 18 - 24 | AC10: Occasionally
A11: 10 | B11: 0 | C11: 1 | D11: 0 | E11: 0 | F11: 0 | G11: 1 | H11: Never | I11: Lack of awareness | J11: No, I usually hear things well | K11: Only in noisy places | L11: Less than 1 hour | M11: 4 | N11: I've never taken a hearing test | O11: Maybe, if it's easy to use | P11: 1 | Q11: 1 | R11: 1 | S11: 1 | T11: 1 | U11: 1 | V11: 1 | W11: 1 | X11: 1 | Y11: 1 | Z11: Yes | AA11: No, I prefer getting tested at a hospital | AB11: 18 - 24 | AC11: Occasionally
A12: 11 | B12: 0 | C12: 1 | D12: 0 | E12: 0 | F12: 0 | G12: 0 | H12: Rarely | I12: Lack of awareness | J12: I'm not sure, but I have felt disconnected | K12: Only in noisy places | L12: More than 4 hours | M12: 4 | N12: I've never taken a hearing test | O12: Maybe, if it's easy to use | P12: 1 | Q12: 0 | R12: 0 | S12: 1 | T12: 0 | U12: 1 | V12: 0 | W12: 0 | X12: 0 | Y12: 0 | Z12: Yes | AA12: No, I prefer getting tested at a hospital | AB12: 18 - 24 | AC12: Occasionally
A13: 12 | B13: 0 | C13: 1 | D13: 0 | E13: 0 | F13: 0 | G13: 0 | H13: Yes often | I13: Cost | J13: Yes, during important work or school meetings | K13: Yes, often | L13: 1-2 hours | M13: 5 | N13: Mobile app | O13: Yes, that would be helpful | P13: 1 | Q13: 0 | R13: 1 | S13: 0 | T13: 0 | U13: 0 | V13: 1 | W13: 0 | X13: 0 | Y13: 0 | Z13: Yes | AA13: Yes, definitely | AB13: 18 - 24 | AC13: Yes
... A388: 387 | B388: 0 | C388: 0 | D388: 0 | E388: 0 | F388: 0 | G388: 1 | H388: Sometimes | I388: Lack of awareness | J388: No, I usually hear things well | K388: Sometimes | L388: 2-4 hours | M388: 4 | N388: I've never taken a hearing test | O388: Yes, that would be helpful | P388: 1 | Q388: 1 | R388: 1 | S388: 1 | T388: 1 | U388: 1 | V388: 1 | W388: 1 | X388: 1 | Y388: 1 | Z388: Yes | AA388: Maybe, if it offers good value | AB388: 18 - 24 | AC388: Yes

Sheet Transformed and Cleaned Data
A1: L.P | B1: Perceived_Hearing_Meaning | C1: Feeling close to loved ones | D1: Staying connected with the world | E1: I haven't thought about it much | F1: Peace and Calm to Brain soulfully | G1: Staying independent and alert | H1: Enjoying music, laughter, and life | I1: Hearing_FOMO | J1: Hearing_Test_Barrier | K1: Hearing_Test_Barrier_Modified | L1: Missed_Important_Sounds | M1: Left_Out_Due_To_Hearing | N1: Daily_Headphone_Use | O1: Belief_Early_Hearing_Care | P1: Last_Hearing_Test_Method | Q1: Interest_in_Hearing_App | R1: Desired_App_Features | S1: Quick tests | T1: Doctor consultation | U1: Game-based interaction | V1: Earphone calibration | W1: Soft guidance | X1: Regular testing reminders | Y1: Detailed report generation | Z1: Personalized volume adjustments | AA1: Audio amplifier or sound booster | AB1: Report sharing options | AC1: Awareness_on_hearing_and_Willingness_to_invest | AD1: Paid_App_Test_Interest | AE1: Age_group | AF1: Ear_Discomfort_After_Use
A2: 1 | B2: Staying independent and alert, Enjoying music, laughter, and life, Staying connected with the world | C2: =IFERROR(IF(SEARCH(C$1,$B2)>0,1,0),0) -> 0 | D2: =IFERROR(IF(SEARCH(D$1,$B2)>0,1,0),0) -> 1 | E2: =IFERROR(IF(SEARCH(E$1,$B2)>0,1,0),0) -> 0 | F2: =IFERROR(IF(SEARCH(F$1,$B2)>0,1,0),0) -> 0 | G2: =IFERROR(IF(SEARCH(G$1,$B2)>0,1,0),0) -> 1 | H2: =IFERROR(IF(SEARCH(H$1,$B2)>0,1,0),0) -> 1 | I2: Sometimes | J2: Cost | K2: =_xlfn.XLOOKUP(J2,Worksheet!$F$1:$F$48,Worksheet!$G$1:$G$48,0) -> Cost | L2: Yes, in family conversations | M2: Yes, often | N2: NA | O2: 5 | P2: Self - application | Q2: Yes, that would be helpful | R2: Privacy, Soft guidance, Visuals, Report sharing options | S2: =IFERROR(IF(SEARCH(S$1,$R2)>0,1,0),0) -> 0 | T2: =IFERROR(IF(SEARCH(T$1,$R2)>0,1,0),0) -> 0 | U2: =IFERROR(IF(SEARCH(U$1,$R2)>0,1,0),0) -> 0 | V2: =IFERROR(IF(SEARCH(V$1,$R2)>0,1,0),0) -> 0 | W2: =IFERROR(IF(SEARCH(W$1,$R2)>0,1,0),0) -> 1 | X2: =IFERROR(IF(SEARCH(X$1,$R2)>0,1,0),0) -> 0 | Y2: =IFERROR(IF(SEARCH(Y$1,$R2)>0,1,0),0) -> 0 | Z2: =IFERROR(IF(SEARCH(Z$1,$R2)>0,1,0),0) -> 0 | ... AB2: =IFERROR(IF(SEARCH(AB$1,$R2)>0,1,0),0) -> 1 | AC2: Yes | AD2: Maybe, if it offers good value | AE2: 18 - 24 | AF2: No
A3: 2 | B3: Staying independent and alert, Staying connected with the world | C3: =IFERROR(IF(SEARCH(C$1,$B3)>0,1,0),0) -> 0 | D3: =IFERROR(IF(SEARCH(D$1,$B3)>0,1,0),0) -> 1 | E3: =IFERROR(IF(SEARCH(E$1,$B3)>0,1,0),0) -> 0 | F3: =IFERROR(IF(SEARCH(F$1,$B3)>0,1,0),0) -> 0 | G3: =IFERROR(IF(SEARCH(G$1,$B3)>0,1,0),0) -> 1 | H3: =IFERROR(IF(SEARCH(H$1,$B3)>0,1,0),0) -> 0 | I3: Rarely | J3: Never felt the need | K3: =_xlfn.XLOOKUP(J3,Worksheet!$F$1:$F$48,Worksheet!$G$1:$G$48,0) -> No need | L3: Yes, in public spaces (trains, shops, announcements) | M3: Only in noisy places | N3: NA | O3: 5 | P3: Self - application | Q3: Yes, that would be helpful | R3: Privacy | S3: =IFERROR(IF(SEARCH(S$1,$R3)>0,1,0),0) -> 0 | T3: =IFERROR(IF(SEARCH(T$1,$R3)>0,1,0),0) -> 0 | U3: =IFERROR(IF(SEARCH(U$1,$R3)>0,1,0),0) -> 0 | V3: =IFERROR(IF(SEARCH(V$1,$R3)>0,1,0),0) -> 0 | W3: =IFERROR(IF(SEARCH(W$1,$R3)>0,1,0),0) -> 0 | X3: =IFERROR(IF(SEARCH(X$1,$R3)>0,1,0),0) -> 0 | Y3: =IFERROR(IF(SEARCH(Y$1,$R3)>0,1,0),0) -> 0 | Z3: =IFERROR(IF(SEARCH(Z$1,$R3)>0,1,0),0) -> 0 | ... AB3: =IFERROR(IF(SEARCH(AB$1,$R3)>0,1,0),0) -> 0 | AC3: Yes | AD3: No, I prefer getting tested at a hospital | AE3: 18 - 24 | AF3: Yes
A4: 3 | B4: Staying independent and alert, I haven't thought about it much | C4: =IFERROR(IF(SEARCH(C$1,$B4)>0,1,0),0) -> 0 | D4: =IFERROR(IF(SEARCH(D$1,$B4)>0,1,0),0) -> 0 | E4: =IFERROR(IF(SEARCH(E$1,$B4)>0,1,0),0) -> 1 | F4: =IFERROR(IF(SEARCH(F$1,$B4)>0,1,0),0) -> 0 | G4: =IFERROR(IF(SEARCH(G$1,$B4)>0,1,0),0) -> 1 | H4: =IFERROR(IF(SEARCH(H$1,$B4)>0,1,0),0) -> 0 | I4: Rarely | J4: Shame | K4: =_xlfn.XLOOKUP(J4,Worksheet!$F$1:$F$48,Worksheet!$G$1:$G$48,0) -> Shame | L4: Yes, during important work or school meetings | M4: Sometimes | N4: NA | O4: 5 | P4: Self - application | Q4: Maybe, if it's easy to use | R4: Soft guidance | S4: =IFERROR(IF(SEARCH(S$1,$R4)>0,1,0),0) -> 0 | T4: =IFERROR(IF(SEARCH(T$1,$R4)>0,1,0),0) -> 0 | U4: =IFERROR(IF(SEARCH(U$1,$R4)>0,1,0),0) -> 0 | V4: =IFERROR(IF(SEARCH(V$1,$R4)>0,1,0),0) -> 0 | W4: =IFERROR(IF(SEARCH(W$1,$R4)>0,1,0),0) -> 1 | X4: =IFERROR(IF(SEARCH(X$1,$R4)>0,1,0),0) -> 0 | Y4: =IFERROR(IF(SEARCH(Y$1,$R4)>0,1,0),0) -> 0 | Z4: =IFERROR(IF(SEARCH(Z$1,$R4)>0,1,0),0) -> 0 | ... AB4: =IFERROR(IF(SEARCH(AB$1,$R4)>0,1,0),0) -> 0 | AC4: No | AD4: Yes, definitely | AE4: 18 - 24 | AF4: Maybe
A5: 4 | B5: Staying independent and alert | C5: =IFERROR(IF(SEARCH(C$1,$B5)>0,1,0),0) -> 0 | D5: =IFERROR(IF(SEARCH(D$1,$B5)>0,1,0),0) -> 0 | E5: =IFERROR(IF(SEARCH(E$1,$B5)>0,1,0),0) -> 0 | F5: =IFERROR(IF(SEARCH(F$1,$B5)>0,1,0),0) -> 0 | G5: =IFERROR(IF(SEARCH(G$1,$B5)>0,1,0),0) -> 1 | H5: =IFERROR(IF(SEARCH(H$1,$B5)>0,1,0),0) -> 0 | I5: Yes often | J5: Lack of awareness | K5: =_xlfn.XLOOKUP(J5,Worksheet!$F$1:$F$48,Worksheet!$G$1:$G$48,0) -> Lack of awareness | L5: Yes, during important work or school meetings | M5: Sometimes | N5: 1-2 hours | O5: 4 | P5: I've never taken a hearing test | Q5: Yes, that would be helpful | R5: Game-based interaction | S5: =IFERROR(IF(SEARCH(S$1,$R5)>0,1,0),0) -> 0 | T5: =IFERROR(IF(SEARCH(T$1,$R5)>0,1,0),0) -> 0 | U5: =IFERROR(IF(SEARCH(U$1,$R5)>0,1,0),0) -> 1 | V5: =IFERROR(IF(SEARCH(V$1,$R5)>0,1,0),0) -> 0 | W5: =IFERROR(IF(SEARCH(W$1,$R5)>0,1,0),0) -> 0 | X5: =IFERROR(IF(SEARCH(X$1,$R5)>0,1,0),0) -> 0 | Y5: =IFERROR(IF(SEARCH(Y$1,$R5)>0,1,0),0) -> 0 | Z5: =IFERROR(IF(SEARCH(Z$1,$R5)>0,1,0),0) -> 0 | ... AB5: =IFERROR(IF(SEARCH(AB$1,$R5)>0,1,0),0) -> 0 | AC5: Yes | AD5: Yes, definitely | AE5: 18 - 24 | AF5: Occasionally
A6: 5 | B6: Staying independent and alert | C6: =IFERROR(IF(SEARCH(C$1,$B6)>0,1,0),0) -> 0 | D6: =IFERROR(IF(SEARCH(D$1,$B6)>0,1,0),0) -> 0 | E6: =IFERROR(IF(SEARCH(E$1,$B6)>0,1,0),0) -> 0 | F6: =IFERROR(IF(SEARCH(F$1,$B6)>0,1,0),0) -> 0 | G6: =IFERROR(IF(SEARCH(G$1,$B6)>0,1,0),0) -> 1 | H6: =IFERROR(IF(SEARCH(H$1,$B6)>0,1,0),0) -> 0 | I6: Never | J6: Lack of awareness | K6: =_xlfn.XLOOKUP(J6,Worksheet!$F$1:$F$48,Worksheet!$G$1:$G$48,0) -> Lack of awareness | L6: No, I usually hear things well | M6: Only in noisy places | N6: Less than 1 hour | O6: 5 | P6: I've never taken a hearing test | Q6: No, I don't think it's necessary | R6: Quick tests, Game-based interaction, Detailed report generation | S6: =IFERROR(IF(SEARCH(S$1,$R6)>0,1,0),0) -> 1 | T6: =IFERROR(IF(SEARCH(T$1,$R6)>0,1,0),0) -> 0 | U6: =IFERROR(IF(SEARCH(U$1,$R6)>0,1,0),0) -> 1 | V6: =IFERROR(IF(SEARCH(V$1,$R6)>0,1,0),0) -> 0 | W6: =IFERROR(IF(SEARCH(W$1,$R6)>0,1,0),0) -> 0 | X6: =IFERROR(IF(SEARCH(X$1,$R6)>0,1,0),0) -> 0 | Y6: =IFERROR(IF(SEARCH(Y$1,$R6)>0,1,0),0) -> 1 | Z6: =IFERROR(IF(SEARCH(Z$1,$R6)>0,1,0),0) -> 0 | ... AB6: =IFERROR(IF(SEARCH(AB$1,$R6)>0,1,0),0) -> 0 | AC6: No | AD6: No, I prefer getting tested at a hospital | AE6: 25 - 34 | AF6: No
A7: 6 | B7: Enjoying music, laughter, and life | C7: =IFERROR(IF(SEARCH(C$1,$B7)>0,1,0),0) -> 0 | D7: =IFERROR(IF(SEARCH(D$1,$B7)>0,1,0),0) -> 0 | E7: =IFERROR(IF(SEARCH(E$1,$B7)>0,1,0),0) -> 0 | F7: =IFERROR(IF(SEARCH(F$1,$B7)>0,1,0),0) -> 0 | G7: =IFERROR(IF(SEARCH(G$1,$B7)>0,1,0),0) -> 0 | H7: =IFERROR(IF(SEARCH(H$1,$B7)>0,1,0),0) -> 1 | I7: Rarely | J7: Lack of awareness | K7: =_xlfn.XLOOKUP(J7,Worksheet!$F$1:$F$48,Worksheet!$G$1:$G$48,0) -> Lack of awareness | L7: Yes, in family conversations | M7: Never | N7: Less than 1 hour | O7: 5 | P7: I've never taken a hearing test | Q7: No, I don't think it's necessary | R7: Quick tests | S7: =IFERROR(IF(SEARCH(S$1,$R7)>0,1,0),0) -> 1 | T7: =IFERROR(IF(SEARCH(T$1,$R7)>0,1,0),0) -> 0 | U7: =IFERROR(IF(SEARCH(U$1,$R7)>0,1,0),0) -> 0 | V7: =IFERROR(IF(SEARCH(V$1,$R7)>0,1,0),0) -> 0 | W7: =IFERROR(IF(SEARCH(W$1,$R7)>0,1,0),0) -> 0 | X7: =IFERROR(IF(SEARCH(X$1,$R7)>0,1,0),0) -> 0 | Y7: =IFERROR(IF(SEARCH(Y$1,$R7)>0,1,0),0) -> 0 | Z7: =IFERROR(IF(SEARCH(Z$1,$R7)>0,1,0),0) -> 0 | ... AB7: =IFERROR(IF(SEARCH(AB$1,$R7)>0,1,0),0) -> 0 | AC7: Yes | AD7: No, I prefer getting tested at a hospital | AE7: 25 - 34 | AF7: No
A8: 7 | B8: Feeling close to loved ones, Staying independent and alert | C8: =IFERROR(IF(SEARCH(C$1,$B8)>0,1,0),0) -> 1 | D8: =IFERROR(IF(SEARCH(D$1,$B8)>0,1,0),0) -> 0 | E8: =IFERROR(IF(SEARCH(E$1,$B8)>0,1,0),0) -> 0 | F8: =IFERROR(IF(SEARCH(F$1,$B8)>0,1,0),0) -> 0 | G8: =IFERROR(IF(SEARCH(G$1,$B8)>0,1,0),0) -> 1 | H8: =IFERROR(IF(SEARCH(H$1,$B8)>0,1,0),0) -> 0 | I8: Yes often | J8: Lack of awareness | K8: =_xlfn.XLOOKUP(J8,Worksheet!$F$1:$F$48,Worksheet!$G$1:$G$48,0) -> Lack of awareness | L8: Yes, in family conversations | M8: Only in noisy places | N8: 2-4 hours | O8: 4 | P8: At a hospital or clinic | Q8: Yes, that would be helpful | R8: Quick tests, Game-based interaction | S8: =IFERROR(IF(SEARCH(S$1,$R8)>0,1,0),0) -> 1 | T8: =IFERROR(IF(SEARCH(T$1,$R8)>0,1,0),0) -> 0 | U8: =IFERROR(IF(SEARCH(U$1,$R8)>0,1,0),0) -> 1 | V8: =IFERROR(IF(SEARCH(V$1,$R8)>0,1,0),0) -> 0 | W8: =IFERROR(IF(SEARCH(W$1,$R8)>0,1,0),0) -> 0 | X8: =IFERROR(IF(SEARCH(X$1,$R8)>0,1,0),0) -> 0 | Y8: =IFERROR(IF(SEARCH(Y$1,$R8)>0,1,0),0) -> 0 | Z8: =IFERROR(IF(SEARCH(Z$1,$R8)>0,1,0),0) -> 0 | ... AB8: =IFERROR(IF(SEARCH(AB$1,$R8)>0,1,0),0) -> 0 | AC8: Yes | AD8: Maybe, if it offers good value | AE8: 18 - 24 | AF8: Yes
A9: 8 | B9: Feeling close to loved ones, Staying independent and alert, Enjoying music, laughter, and life, Staying connected with the world | C9: =IFERROR(IF(SEARCH(C$1,$B9)>0,1,0),0) -> 1 | D9: =IFERROR(IF(SEARCH(D$1,$B9)>0,1,0),0) -> 1 | E9: =IFERROR(IF(SEARCH(E$1,$B9)>0,1,0),0) -> 0 | F9: =IFERROR(IF(SEARCH(F$1,$B9)>0,1,0),0) -> 0 | G9: =IFERROR(IF(SEARCH(G$1,$B9)>0,1,0),0) -> 1 | H9: =IFERROR(IF(SEARCH(H$1,$B9)>0,1,0),0) -> 1 | I9: Rarely | J9: Cost, Lack of awareness | K9: =_xlfn.XLOOKUP(J9,Worksheet!$F$1:$F$48,Worksheet!$G$1:$G$48,0) -> Cost | L9: No, I usually hear things well | M9: Never | N9: 2-4 hours | O9: 4 | P9: At a hospital or clinic | Q9: Maybe, if it's easy to use | R9: Quick tests, Game-based interaction, Regular testing reminders, Personalized volume adjustments | S9: =IFERROR(IF(SEARCH(S$1,$R9)>0,1,0),0) -> 1 | T9: =IFERROR(IF(SEARCH(T$1,$R9)>0,1,0),0) -> 0 | U9: =IFERROR(IF(SEARCH(U$1,$R9)>0,1,0),0) -> 1 | V9: =IFERROR(IF(SEARCH(V$1,$R9)>0,1,0),0) -> 0 | W9: =IFERROR(IF(SEARCH(W$1,$R9)>0,1,0),0) -> 0 | X9: =IFERROR(IF(SEARCH(X$1,$R9)>0,1,0),0) -> 1 | Y9: =IFERROR(IF(SEARCH(Y$1,$R9)>0,1,0),0) -> 0 | Z9: =IFERROR(IF(SEARCH(Z$1,$R9)>0,1,0),0) -> 1 | ... AB9: =IFERROR(IF(SEARCH(AB$1,$R9)>0,1,0),0) -> 0 | AC9: Yes | AD9: Yes, definitely | AE9: 18 - 24 | AF9: Yes
A10: 9 | B10: Enjoying music, laughter, and life | C10: =IFERROR(IF(SEARCH(C$1,$B10)>0,1,0),0) -> 0 | D10: =IFERROR(IF(SEARCH(D$1,$B10)>0,1,0),0) -> 0 | E10: =IFERROR(IF(SEARCH(E$1,$B10)>0,1,0),0) -> 0 | F10: =IFERROR(IF(SEARCH(F$1,$B10)>0,1,0),0) -> 0 | G10: =IFERROR(IF(SEARCH(G$1,$B10)>0,1,0),0) -> 0 | H10: =IFERROR(IF(SEARCH(H$1,$B10)>0,1,0),0) -> 1 | I10: Sometimes | J10: Lack of awareness | K10: =_xlfn.XLOOKUP(J10,Worksheet!$F$1:$F$48,Worksheet!$G$1:$G$48,0) -> Lack of awareness | L10: Yes, in public spaces (trains, shops, announcements) | M10: Only in noisy places | N10: Less than 1 hour | O10: 5 | P10: I've never taken a hearing test | Q10: Yes, that would be helpful | R10: Quick tests, Game-based interaction, Regular testing reminders, Doctor consultation, Audio amplifier or sound booster | S10: =IFERROR(IF(SEARCH(S$1,$R10)>0,1,0),0) -> 1 | T10: =IFERROR(IF(SEARCH(T$1,$R10)>0,1,0),0) -> 1 | U10: =IFERROR(IF(SEARCH(U$1,$R10)>0,1,0),0) -> 1 | V10: =IFERROR(IF(SEARCH(V$1,$R10)>0,1,0),0) -> 0 | W10: =IFERROR(IF(SEARCH(W$1,$R10)>0,1,0),0) -> 0 | X10: =IFERROR(IF(SEARCH(X$1,$R10)>0,1,0),0) -> 1 | Y10: =IFERROR(IF(SEARCH(Y$1,$R10)>0,1,0),0) -> 0 | Z10: =IFERROR(IF(SEARCH(Z$1,$R10)>0,1,0),0) -> 0 | ... AB10: =IFERROR(IF(SEARCH(AB$1,$R10)>0,1,0),0) -> 0 | AC10: Yes | AD10: Maybe, if it offers good value | AE10: 18 - 24 | AF10: Occasionally
A11: 10 | B11: Enjoying music, laughter, and life, Staying connected with the world | C11: =IFERROR(IF(SEARCH(C$1,$B11)>0,1,0),0) -> 0 | D11: =IFERROR(IF(SEARCH(D$1,$B11)>0,1,0),0) -> 1 | E11: =IFERROR(IF(SEARCH(E$1,$B11)>0,1,0),0) -> 0 | F11: =IFERROR(IF(SEARCH(F$1,$B11)>0,1,0),0) -> 0 | G11: =IFERROR(IF(SEARCH(G$1,$B11)>0,1,0),0) -> 0 | H11: =IFERROR(IF(SEARCH(H$1,$B11)>0,1,0),0) -> 1 | I11: Never | J11: Lack of awareness | K11: =_xlfn.XLOOKUP(J11,Worksheet!$F$1:$F$48,Worksheet!$G$1:$G$48,0) -> Lack of awareness | L11: No, I usually hear things well | M11: Only in noisy places | N11: Less than 1 hour | O11: 4 | P11: I've never taken a hearing test | Q11: Maybe, if it's easy to use | R11: Quick tests, Game-based interaction, Earphone calibration, Regular testing reminders, Detailed report generation, Doctor consultation, Audio amplifier or sound booster, Personalized volume adjustments, Soft guidance, Report sharing options | S11: =IFERROR(IF(SEARCH(S$1,$R11)>0,1,0),0) -> 1 | T11: =IFERROR(IF(SEARCH(T$1,$R11)>0,1,0),0) -> 1 | U11: =IFERROR(IF(SEARCH(U$1,$R11)>0,1,0),0) -> 1 | V11: =IFERROR(IF(SEARCH(V$1,$R11)>0,1,0),0) -> 1 | W11: =IFERROR(IF(SEARCH(W$1,$R11)>0,1,0),0) -> 1 | X11: =IFERROR(IF(SEARCH(X$1,$R11)>0,1,0),0) -> 1 | Y11: =IFERROR(IF(SEARCH(Y$1,$R11)>0,1,0),0) -> 1 | Z11: =IFERROR(IF(SEARCH(Z$1,$R11)>0,1,0),0) -> 1 | ... AB11: =IFERROR(IF(SEARCH(AB$1,$R11)>0,1,0),0) -> 1 | AC11: Yes | AD11: No, I prefer getting tested at a hospital | AE11: 18 - 24 | AF11: Occasionally
A12: 11 | B12: Staying connected with the world | C12: =IFERROR(IF(SEARCH(C$1,$B12)>0,1,0),0) -> 0 | D12: =IFERROR(IF(SEARCH(D$1,$B12)>0,1,0),0) -> 1 | E12: =IFERROR(IF(SEARCH(E$1,$B12)>0,1,0),0) -> 0 | F12: =IFERROR(IF(SEARCH(F$1,$B12)>0,1,0),0) -> 0 | G12: =IFERROR(IF(SEARCH(G$1,$B12)>0,1,0),0) -> 0 | H12: =IFERROR(IF(SEARCH(H$1,$B12)>0,1,0),0) -> 0 | I12: Rarely | J12: Lack of awareness | K12: =_xlfn.XLOOKUP(J12,Worksheet!$F$1:$F$48,Worksheet!$G$1:$G$48,0) -> Lack of awareness | L12: I'm not sure, but I have felt disconnected | M12: Only in noisy places | N12: More than 4 hours | O12: 4 | P12: I've never taken a hearing test | Q12: Maybe, if it's easy to use | R12: Quick tests, Earphone calibration, Regular testing reminders | S12: =IFERROR(IF(SEARCH(S$1,$R12)>0,1,0),0) -> 1 | T12: =IFERROR(IF(SEARCH(T$1,$R12)>0,1,0),0) -> 0 | U12: =IFERROR(IF(SEARCH(U$1,$R12)>0,1,0),0) -> 0 | V12: =IFERROR(IF(SEARCH(V$1,$R12)>0,1,0),0) -> 1 | W12: =IFERROR(IF(SEARCH(W$1,$R12)>0,1,0),0) -> 0 | X12: =IFERROR(IF(SEARCH(X$1,$R12)>0,1,0),0) -> 1 | Y12: =IFERROR(IF(SEARCH(Y$1,$R12)>0,1,0),0) -> 0 | Z12: =IFERROR(IF(SEARCH(Z$1,$R12)>0,1,0),0) -> 0 | ... AB12: =IFERROR(IF(SEARCH(AB$1,$R12)>0,1,0),0) -> 0 | AC12: Yes | AD12: No, I prefer getting tested at a hospital | AE12: 18 - 24 | AF12: Occasionally
A13: 12 | B13: Staying connected with the world | C13: =IFERROR(IF(SEARCH(C$1,$B13)>0,1,0),0) -> 0 | D13: =IFERROR(IF(SEARCH(D$1,$B13)>0,1,0),0) -> 1 | E13: =IFERROR(IF(SEARCH(E$1,$B13)>0,1,0),0) -> 0 | F13: =IFERROR(IF(SEARCH(F$1,$B13)>0,1,0),0) -> 0 | G13: =IFERROR(IF(SEARCH(G$1,$B13)>0,1,0),0) -> 0 | H13: =IFERROR(IF(SEARCH(H$1,$B13)>0,1,0),0) -> 0 | I13: Yes often | J13: Cost | K13: =_xlfn.XLOOKUP(J13,Worksheet!$F$1:$F$48,Worksheet!$G$1:$G$48,0) -> Cost | L13: Yes, during important work or school meetings | M13: Yes, often | N13: 1-2 hours | O13: 5 | P13: Mobile app | Q13: Yes, that would be helpful | R13: Quick tests, Game-based interaction, Detailed report generation | S13: =IFERROR(IF(SEARCH(S$1,$R13)>0,1,0),0) -> 1 | T13: =IFERROR(IF(SEARCH(T$1,$R13)>0,1,0),0) -> 0 | U13: =IFERROR(IF(SEARCH(U$1,$R13)>0,1,0),0) -> 1 | V13: =IFERROR(IF(SEARCH(V$1,$R13)>0,1,0),0) -> 0 | W13: =IFERROR(IF(SEARCH(W$1,$R13)>0,1,0),0) -> 0 | X13: =IFERROR(IF(SEARCH(X$1,$R13)>0,1,0),0) -> 0 | Y13: =IFERROR(IF(SEARCH(Y$1,$R13)>0,1,0),0) -> 1 | Z13: =IFERROR(IF(SEARCH(Z$1,$R13)>0,1,0),0) -> 0 | ... AB13: =IFERROR(IF(SEARCH(AB$1,$R13)>0,1,0),0) -> 0 | AC13: Yes | AD13: Yes, definitely | AE13: 18 - 24 | AF13: Yes
... A388: 387 | B388: Enjoying music, laughter, and life | C388: =IFERROR(IF(SEARCH(C$1,$B388)>0,1,0),0) -> 0 | D388: =IFERROR(IF(SEARCH(D$1,$B388)>0,1,0),0) -> 0 | E388: =IFERROR(IF(SEARCH(E$1,$B388)>0,1,0),0) -> 0 | F388: =IFERROR(IF(SEARCH(F$1,$B388)>0,1,0),0) -> 0 | G388: =IFERROR(IF(SEARCH(G$1,$B388)>0,1,0),0) -> 0 | H388: =IFERROR(IF(SEARCH(H$1,$B388)>0,1,0),0) -> 1 | I388: Sometimes | J388: Lack of awareness | K388: =_xlfn.XLOOKUP(J388,Worksheet!$F$1:$F$48,Worksheet!$G$1:$G$48,0) -> Lack of awareness | L388: No, I usually hear things well | M388: Sometimes | N388: 2-4 hours | O388: 4 | P388: I've never taken a hearing test | Q388: Yes, that would be helpful | R388: Quick tests, Game-based interaction, Earphone calibration, Regular testing reminders, Detailed report generation, Doctor consultation, Audio amplifier or sound booster, Personalized volume adjustments, Soft guidance, Report sharing options | S388: =IFERROR(IF(SEARCH(S$1,$R388)>0,1,0),0) -> 1 | T388: =IFERROR(IF(SEARCH(T$1,$R388)>0,1,0),0) -> 1 | U388: =IFERROR(IF(SEARCH(U$1,$R388)>0,1,0),0) -> 1 | V388: =IFERROR(IF(SEARCH(V$1,$R388)>0,1,0),0) -> 1 | W388: =IFERROR(IF(SEARCH(W$1,$R388)>0,1,0),0) -> 1 | X388: =IFERROR(IF(SEARCH(X$1,$R388)>0,1,0),0) -> 1 | Y388: =IFERROR(IF(SEARCH(Y$1,$R388)>0,1,0),0) -> 1 | Z388: =IFERROR(IF(SEARCH(Z$1,$R388)>0,1,0),0) -> 1 | ... AB388: =IFERROR(IF(SEARCH(AB$1,$R388)>0,1,0),0) -> 1 | AC388: Yes | AD388: Maybe, if it offers good value | AE388: 18 - 24 | AF388: Yes

Sheet Worksheet
A1: 1 | B1: Cost | F1: Cost | G1: Cost
A2: 2 | B2: Never felt the need | C2: Lack of awareness | D2: I haven't had the need to | E2: yet | F2: Never felt the need | G2: No need
A3: 3 | B3: Shame | C3: probably? | F3: Shame | G3: Shame
A4: 4 | B4: Lack of awareness | F4: Lack of awareness | G4: Lack of awareness
A5: 5 | B5: Not that much required | C5: Also | F5: Cost, Lack of awareness | G5: Cost
A6: 6 | B6: Never had a situation to get tested. | C6: Shame | F6: Not that much required | G6: No need
A7: 7 | B7: Fear | C7: Cost | F7: Never had a situation to get tested. | G7: Never done
A8: 8 | B8: None of the above | C8: Facilities | F8: Fear | G8: Fear
A9: 9 | B9: I never had any issues | F9: None of the above | G9: NA
A10: 10 | B10: NA | F10: I never had any issues | G10: Never done
A11: 11 | B11: I never thought I need one | F11: NA | G11: NA
A12: 12 | B12: I don't have a hearing problem | F12: Fear, Lack of awareness | G12: Fear
A13: 13 | B13: My hearing is good ðŸ¤·â€â™‚ï¸ | F13: I never thought I need one, probably? | G13: Lack of awareness
A14: 14 | B14: None | F14: Lack of awareness, | G14: Lack of awareness
A15: 15 | B15: Not finding any difficulties now | F15: I don't have a hearing problem | G15: No need
A16: 16 | B16: Not required | F16: My hearing is good ðŸ¤·â€â™‚ï¸ | G16: No need
A17: 17 | B17: No hearing issues | F17: None | G17: NA
A18: 18 | B18: I don't have problem in hearing. | F18: Lack of awareness, Also, I haven't had the need to, yet | G18: Lack of awareness
A19: 19 | B19: I have good hearing | F19: Not finding any difficulties now | G19: No need
A20: 20 | B20: i didnt feel like there is any change | F20: Not required | G20: No need
... A40: 40 | B40: I frequently testing by every six months | F40: Just testing | G40: Testing
A41: 41 | F41: No significant problems or concerning symptoms | G41: No need
A42: 42 | F42: I am doing hearing test periodically | G42: Testing
A43: 43 | F43: Not applicable | G43: NA
A44: 44 | F44: Never had the necessity to | G44: No need
A45: 45 | F45: Cost, Facilities | G45: Cost
A46: 46 | F46: Not necessary | G46: No need
A47: 47 | F47: Never thought about it | G47: Lack of awareness
A48: 48 | F48: I frequently testing by every six months | G48: Testing
A49: 49
A50: 50
A51: 51
A52: 52
A53: 53
A54: 54
A55: 55
A56: 56
A57: 57
A58: 58
A59: 59
...

Sheet Raw Data
A1: Perceived_Hearing_Meaning.1 | B1: Perceived_Hearing_Meaning.2 | C1: Hearing_FOMO | D1: Hearing_Test_Barrier | E1: Missed_Important_Sounds | F1: Left_Out_Due_To_Hearing | G1: Daily_Headphone_Use | H1: Belief_Early_Hearing_Care | I1: Last_Hearing_Test_Method | J1: Interest_in_Hearing_App | K1: Desired_App_Features | L1: Awareness_on_hearing_and_Willingness_to_invest | M1: Paid_App_Test_Interest | N1: Age_group | O1: Ear_Discomfort_After_Use
A2: Staying independent and alert, Enjoying music, laughter, and life, Staying connected with the world | C2: Sometimes | D2: Cost | E2: Yes, in family conversations | F2: Yes, often | G2: My parent(s) | H2: 5 | I2: Self - application, Loved one, AI Support | J2: Yes | K2: Privacy, Soft guidance, Visuals, Report sharing options | L2: Yes | M2: Maybe, if it offers good value | N2: 18 - 24 | O2: No
A3: Staying independent and alert, Staying connected with the world | C3: Rarely | D3: Never felt the need | E3: Yes, in public spaces (trains, shops, announcements) | F3: Only in noisy places | G3: My child/children | H3: 5 | I3: Self - application | J3: Yes | K3: Privacy | L3: Yes | M3: No, I prefer getting tested at a hospital | N3: 18 - 24 | O3: Yes
A4: Staying independent and alert, I havenâ€™t thought about it much | C4: Rarely | D4: Shame | E4: Yes, during important work or school meetings | F4: Sometimes | G4: My parent(s) | H4: 5 | I4: Self - application | J4: Maybe | K4: Soft guidance | L4: No | M4: Yes, definitely | N4: 18 - 24 | O4: Maybe
A5: Staying independent and alert | C5: Yes often | D5: Lack of awareness | E5: Yes, during important work or school meetings | F5: Sometimes | G5: 1-2 hours | H5: 4 | I5: I've never taken a hearing test | J5: Yes, that would be helpful | K5: Game-based interaction | L5: Yes | M5: Yes, definitely | N5: 18 - 24 | O5: Occasionally
A6: Staying independent and alert | C6: Never | D6: Lack of awareness | E6: No, I usually hear things well | F6: Only in noisy places | G6: Less than 1 hour | H6: 5 | I6: I've never taken a hearing test | J6: No, I don't think it's necessary | K6: Quick tests, Game-based interaction, Detailed report generation | L6: No | M6: No, I prefer getting tested at a hospital | N6: 25 - 34 | O6: No
A7: Enjoying music, laughter, and life | C7: Rarely | D7: Lack of awareness | E7: Yes, in family conversations | F7: Never | G7: Less than 1 hour | H7: 5 | I7: I've never taken a hearing test | J7: No, I don't think it's necessary | K7: Quick tests | L7: Yes | M7: No, I prefer getting tested at a hospital | N7: 25 - 34 | O7: No
A8: Feeling close to loved ones, Staying independent and alert | C8: Yes often | D8: Lack of awareness | E8: Yes, in family conversations | F8: Only in noisy places | G8: 2-4 hours | H8: 4 | I8: At a hospital or clinic | J8: Yes, that would be helpful | K8: Quick tests, Game-based interaction | L8: Yes | M8: Maybe, if it offers good value | N8: 18 - 24 | O8: Yes
A9: Feeling close to loved ones, Staying independent and alert, Enjoying music, laughter, and life, Staying connected with the world | C9: Rarely | D9: Cost, Lack of awareness | E9: No, I usually hear things well | F9: Never | G9: 2-4 hours | H9: 4 | I9: At a hospital or clinic | J9: Maybe, if it's easy to use | K9: Quick tests, Game-based interaction, Regular testing reminders, Personalized volume adjustments | L9: Yes | M9: Yes, definitely | N9: 18 - 24 | O9: Yes
A10: Enjoying music, laughter, and life | C10: Sometimes | D10: Lack of awareness | E10: Yes, in public spaces (trains, shops, announcements) | F10: Only in noisy places | G10: Less than 1 hour | H10: 5 | I10: I've never taken a hearing test | J10: Yes, that would be helpful | K10: Quick tests, Game-based interaction, Regular testing reminders, Doctor consultation, Audio amplifier or sound booster | L10: Yes | M10: Maybe, if it offers good value | N10: 18 - 24 | O10: Occasionally
A11: Enjoying music, laughter, and life, Staying connected with the world | C11: Never | D11: Lack of awareness | E11: No, I usually hear things well | F11: Only in noisy places | G11: Less than 1 hour | H11: 4 | I11: I've never taken a hearing test | J11: Maybe, if it's easy to use | K11: Quick tests, Game-based interaction, Earphone calibration, Regular testing reminders, Detailed report generation, Doctor consultation, Audio amplifier or sound booster, Personalized volume adjustments, Soft guidance, Report sharing options | L11: Yes | M11: No, I prefer getting tested at a hospital | N11: 18 - 24 | O11: Occasionally
A12: Staying connected with the world | C12: Rarely | D12: Lack of awareness | E12: Iâ€™m not sure, but I have felt disconnected | F12: Only in noisy places | G12: More than 4 hours | H12: 4 | I12: I've never taken a hearing test | J12: Maybe, if it's easy to use | K12: Quick tests, Earphone calibration, Regular testing reminders | L12: Yes | M12: No, I prefer getting tested at a hospital | N12: 18 - 24 | O12: Occasionally
A13: Staying connected with the world | C13: Yes often | D13: Cost | E13: Yes, during important work or school meetings | F13: Yes, often | G13: 1-2 hours | H13: 5 | I13: Mobile app | J13: Yes, that would be helpful | K13: Quick tests, Game-based interaction, Detailed report generation | L13: Yes | M13: Yes, definitely | N13: 18 - 24 | O13: Yes
... A388: Enjoying music, laughter, and life | C388: Sometimes | D388: Lack of awareness | E388: No, I usually hear things well | F388: Sometimes | G388: 2-4 hours | H388: 4 | I388: I've never taken a hearing test | J388: Yes, that would be helpful | K388: Quick tests, Game-based interaction, Earphone calibration, Regular testing reminders, Detailed report generation, Doctor consultation, Audio amplifier or sound booster, Personalized volume adjustments, Soft guidance, Report sharing options | L388: Yes | M388: Maybe, if it offers good value | N388: 18 - 24 | O388: Yes
